Workbook

Sheet OBRA 251
B1: BELA NOVA CONSTRUTORA LTDA
B3: DEMONSTRAÇÃO DO RESULTADO APURADO
B5: OBRA 251 - ESTHER TOWERS - EZTEC
B7: OBRA EM ANDAMENTO
B9: Março a Dez/23 | C9: Jan a Dez/24 | D9: Jan a Dez/2025 | E9: Janeiro/2026 | F9: Fevereiro/2026 | G9: Março/2026 | H9: Abril/2026 | I9: Maio/2026 | J9: Junho/2026 | K9: Julho/2026 | L9: Agosto/2026 | M9: Setembro/2026 | N9: Outubro/2026 | O9: Novembro/2026 | P9: Dezembro/2026 | Q9: Acumulado | R9: % S/FAT | X9: 2025
A10: Receitas Brutas
A11: Servicos prestados | B11: 0 | C11: =SUM(E11:P11) -> 0 | D11: =SUM(F11:Q11) -> 0 | E11: 0 | F11: 0 | G11: 0 | H11: 0 | I11: 0 | J11: 0 | K11: 0 | L11: 0 | M11: 0 | N11: 0 | O11: 0 | P11: 0 | Q11: =B11+C11+E11+F11+G11+H11+I11+J11+K11+L11+M11+N11+O11+P11 -> 0 | R11: 1 | T11: =SUM(B11,C11,E11) -> 0 | V11: =T11-Q11 -> 0
A12: Locação de Equipamentos - 450 | B12: 0 | C12: =SUM(E12:P12) -> 0 | D12: =SUM(F12:Q12) -> 0 | E12: 0 | F12: 0 | G12: 0 | H12: 0 | I12: 0 | J12: 0 | K12: 0 | L12: 0 | M12: 0 | N12: 0 | O12: 0 | P12: 0 | Q12: =B12+C12+E12+F12+G12+H12+I12+J12+K12+L12+M12+N12+O12+P12 -> 0 | T12: =SUM(B12,C12,E12) -> 0 | V12: =T12-Q12 -> 0
A13: Receitas Brutas Total... | B13: =SUM(B11:B12) -> 0 | C13: =SUM(C11:C12) -> 0 | D13: =SUM(D11:D12) -> 0 | E13: =SUM(E11:E12) -> 0 | F13: =SUM(F11:F12) -> 0 | G13: =SUM(G11:G12) -> 0 | H13: =SUM(H11:H12) -> 0 | I13: =SUM(I11:I12) -> 0 | ... Q13: =SUM(Q11:Q12) -> 0 | R13: 1 | T13: =SUM(B13,C13,E13) -> 0 | V13: =T13-Q13 -> 0
T14: =SUM(B14,C14,E14) -> 0
A15: Custos | T15: =SUM(B15,C15,E15) -> 0
A16: Alimentação - 320 | B16: -10118.69 | C16: -2203.29 | D16: -46770.85 | E16: -6536.59 | F16: -5430.1 | G16: -5318.8 | H16: -4979.32 | I16: -5067.64 | J16: -3536.82 | K16: 0 | L16: 0 | M16: 0 | N16: 0 | O16: 0 | P16: 0 | Q16: =SUM(B16:P16) -> -89962.1 | T16: =SUM(B16:P16) -> -89962.1 | V16: =Q16-T16 -> 0 | X16: =Q16-C16-B16 -> -77640.12
A17: Combustíveis - 322 | B17: 0 | C17: =SUM(E17:P17) -> 0 | D17: 0 | E17: 0 | F17: 0 | G17: 0 | H17: 0 | I17: 0 | J17: 0 | K17: 0 | L17: 0 | M17: 0 | N17: 0 | O17: 0 | P17: 0 | Q17: =SUM(B17:P17) -> 0 | T17: =SUM(B17:P17) -> 0 | V17: =Q17-T17 -> 0 | X17: =Q17-C17-B17 -> 0
A18: Despesa com Radio e Telefonia Celular | B18: 0 | C18: =SUM(E18:P18) -> 0 | D18: 0 | E18: 0 | F18: 0 | G18: 0 | H18: 0 | I18: 0 | J18: 0 | K18: 0 | L18: 0 | M18: 0 | N18: 0 | O18: 0 | P18: 0 | Q18: =SUM(B18:P18) -> 0 | T18: =SUM(B18:P18) -> 0 | V18: =Q18-T18 -> 0 | X18: =Q18-C18-B18 -> 0
A19: Equipamento de Segurança - EPIs - 360 | B19: 0 | C19: -143.14 | D19: -41.1 | E19: 0 | F19: 0 | G19: 0 | H19: 0 | I19: 0 | J19: 0 | K19: 0 | L19: 0 | M19: 0 | N19: 0 | O19: 0 | P19: 0 | Q19: =SUM(B19:P19) -> -184.24 | T19: =SUM(B19:P19) -> -184.24 | V19: =Q19-T19 -> 0 | X19: =Q19-C19-B19 -> -41.1
A20: Ferias - 315 | B20: -7450.73 | C20: -8327.38 | D20: -37246.46 | E20: -4224.71 | F20: -3562.89 | G20: =-3562.89 -> -3562.89 | H20: -3339.96 | I20: -2266.7 | J20: -2930.17 | K20: 0 | L20: 0 | M20: 0 | N20: 0 | O20: 0 | P20: 0 | Q20: =SUM(B20:P20) -> -72911.89 | T20: =SUM(B20:P20) -> -72911.89 | V20: =Q20-T20 -> 0 | X20: =Q20-C20-B20 -> -57133.78
A21: FGTS - 317 | B21: -5450.68 | C21: -5940.21 | D21: -27685.78 | E21: -2539.14 | F21: -5335.84 | G21: =-2451.92-942.17 -> -3394.09 | H21: -2312.26 | I21: -1513.16 | J21: -1819.93 | K21: 0 | L21: 0 | M21: 0 | N21: 0 | O21: 0 | P21: 0 | Q21: =SUM(B21:P21) -> -55991.09 | T21: =SUM(B21:P21) -> -55991.09 | V21: =Q21-T21 -> 0 | X21: =Q21-C21-B21 -> -44600.2
A22: Horas Extras - 499 | B22: -10981.63 | C22: -9195.55 | D22: -26232.96 | E22: -2167.45 | F22: -3557.58 | G22: -2952.16 | H22: -1732.73 | I22: -760.59 | J22: -1288.42 | K22: 0 | L22: 0 | M22: 0 | N22: 0 | O22: 0 | P22: 0 | Q22: =SUM(B22:P22) -> -58869.07 | T22: =SUM(B22:P22) -> -58869.07 | V22: =Q22-T22 -> 0 | X22: =Q22-C22-B22 -> -38691.89
A23: Indenizações e Aviso Prévio - 318 | B23: 0 | C23: -929.69 | D23: -218.99 | E23: 0 | F23: 0 | G23: 0 | H23: 0 | I23: 0 | J23: 0 | K23: 0 | L23: 0 | M23: 0 | N23: 0 | O23: 0 | P23: 0 | Q23: =SUM(B23:P23) -> -1148.68 | T23: =SUM(B23:P23) -> -1148.68 | V23: =Q23-T23 -> 0 | X23: =Q23-C23-B23 -> -218.99
A24: Indenizações Trabalhistas Judiciais - 369 | B24: 0 | C24: =SUM(E24:P24) -> 0 | D24: 0 | E24: 0 | F24: 0 | G24: 0 | H24: 0 | I24: 0 | J24: 0 | K24: 0 | L24: 0 | M24: 0 | N24: 0 | O24: 0 | P24: 0 | Q24: =SUM(B24:P24) -> 0 | T24: =SUM(B24:P24) -> 0 | V24: =Q24-T24 -> 0 | X24: =Q24-C24-B24 -> 0
A25: INSS - 316 | B25: -6087.45 | C25: -6549.45 | D25: -44939.97 | E25: -5629.42 | F25: -5841.54 | G25: -5615.48 | H25: -5363.61 | I25: -3724 | J25: -4381.26 | K25: 0 | L25: 0 | M25: 0 | N25: 0 | O25: 0 | P25: 0 | Q25: =SUM(B25:P25) -> -88132.18 | T25: =SUM(B25:P25) -> -88132.18 | V25: =Q25-T25 -> 0 | X25: =Q25-C25-B25 -> -75495.28
A26: Locação de Andaimes - 328 | B26: 0 | C26: =SUM(E26:P26) -> 0 | D26: 0 | E26: 0 | F26: 0 | G26: 0 | H26: 0 | I26: 0 | J26: 0 | K26: 0 | L26: 0 | M26: 0 | N26: 0 | O26: 0 | P26: 0 | Q26: =SUM(B26:P26) -> 0 | T26: =SUM(B26:P26) -> 0 | V26: =Q26-T26 -> 0 | X26: =Q26-C26-B26 -> 0
A27: Locação de Máqs, Ferramentas e Equipamentos - | B27: 0 | C27: =SUM(E27:P27) -> 0 | D27: 0 | E27: 0 | F27: 0 | G27: 0 | H27: 0 | I27: 0 | J27: 0 | K27: 0 | L27: 0 | M27: 0 | N27: 0 | O27: 0 | P27: 0 | Q27: =SUM(B27:P27) -> 0 | T27: =SUM(B27:P27) -> 0 | V27: =Q27-T27 -> 0 | X27: =Q27-C27-B27 -> 0
A28: Manutenção de Equipamento - 394 | B28: 0 | C28: =SUM(E28:P28) -> 0 | D28: 0 | E28: 0 | F28: 0 | G28: 0 | H28: 0 | I28: 0 | J28: 0 | K28: 0 | L28: 0 | M28: 0 | N28: 0 | O28: 0 | P28: 0 | Q28: =SUM(B28:P28) -> 0 | T28: =SUM(B28:P28) -> 0 | V28: =Q28-T28 -> 0 | X28: =Q28-C28-B28 -> 0
A29: Manutenção de Veículos - 510 | B29: 0 | C29: =SUM(E29:P29) -> 0 | D29: 0 | E29: 0 | F29: 0 | G29: 0 | H29: 0 | I29: 0 | J29: 0 | K29: 0 | L29: 0 | M29: 0 | N29: 0 | O29: 0 | P29: 0 | Q29: =SUM(B29:P29) -> 0 | T29: =SUM(B29:P29) -> 0 | V29: =Q29-T29 -> 0 | X29: =Q29-C29-B29 -> 0
A30: Medicina Ocupacional e Assist médica - 3 | B30: -1129.53 | C30: -945 | D30: -2655 | E30: -540 | F30: -540 | G30: 0 | H30: 0 | I30: -405 | J30: -270 | K30: 0 | L30: 0 | M30: 0 | N30: 0 | O30: 0 | P30: 0 | Q30: =SUM(B30:P30) -> -6484.53 | T30: =SUM(B30:P30) -> -6484.53 | V30: =Q30-T30 -> 0 | X30: =Q30-C30-B30 -> -4410
A31: Móveis Não Imobilizado - 364 | B31: 0 | C31: =SUM(E31:P31) -> 0 | D31: 0 | E31: 0 | F31: 0 | G31: 0 | H31: 0 | I31: 0 | J31: 0 | K31: 0 | L31: 0 | M31: 0 | N31: 0 | O31: 0 | P31: 0 | Q31: =SUM(B31:P31) -> 0 | T31: =SUM(B31:P31) -> 0 | V31: =Q31-T31 -> 0 | X31: =Q31-C31-B31 -> 0
A32: Peças, Ferramentas e Acessórios - 361 | B32: -82.98 | C32: -52.47 | D32: -52.47 | E32: 0 | F32: 0 | G32: 0 | H32: 0 | I32: 0 | J32: 0 | K32: 0 | L32: 0 | M32: 0 | N32: 0 | O32: 0 | P32: 0 | Q32: =SUM(B32:P32) -> -187.92 | T32: =SUM(B32:P32) -> -187.92 | V32: =Q32-T32 -> 0 | X32: =Q32-C32-B32 -> -52.47
A33: Premios e Gratificacoes - 313 | B33: -13328 | C33: -13234 | D33: -280065.19 | E33: -27000.14 | F33: -29351 | G33: -38254 | H33: -23599 | I33: -14288 | J33: -16583 | K33: 0 | L33: 0 | M33: 0 | N33: 0 | O33: 0 | P33: 0 | Q33: =SUM(B33:P33) -> -455702.33 | T33: =SUM(B33:P33) -> -455702.33 | V33: =Q33-T33 -> 0 | X33: =Q33-C33-B33 -> -429140.33
A34: Salarios e Ordenados - 311 | B34: -57521.82 | C34: -58824.79 | D34: -262861.95 | E34: -29573.7 | F34: -27159.75 | G34: -24143.11 | H34: -27388.23 | I34: -18754.42 | J34: -22058.21 | K34: 0 | L34: 0 | M34: 0 | N34: 0 | O34: 0 | P34: 0 | Q34: =SUM(B34:P34) -> -528285.98 | T34: =SUM(B34:P34) -> -528285.98 | V34: =Q34-T34 -> 0 | X34: =Q34-C34-B34 -> -411939.37
A35: Serviços de Terceiros - 324 | B35: 0 | C35: -405 | D35: -405 | E35: 0 | F35: 0 | G35: 0 | H35: 0 | I35: 0 | J35: 0 | K35: 0 | L35: 0 | M35: 0 | N35: 0 | O35: 0 | P35: 0 | Q35: =SUM(B35:P35) -> -810 | T35: =SUM(B35:P35) -> -810 | V35: =Q35-T35 -> 0 | X35: =Q35-C35-B35 -> -405
A36: Seguro Riscos Execução de Serv. Trab. | B36: 0 | C36: =SUM(E36:P36) -> 0 | D36: 0 | E36: 0 | F36: 0 | G36: 0 | H36: 0 | I36: 0 | J36: 0 | K36: 0 | L36: 0 | M36: 0 | N36: 0 | O36: 0 | P36: 0 | Q36: =SUM(B36:P36) -> 0 | T36: =SUM(B36:P36) -> 0 | V36: =Q36-T36 -> 0 | X36: =Q36-C36-B36 -> 0
A37: Uniformes - 425 | B37: -639.86 | C37: -1211.38 | D37: -2528.41 | E37: 0 | F37: -20.06 | G37: 0 | H37: -153.65 | I37: 0 | J37: 0 | K37: 0 | L37: 0 | M37: 0 | N37: 0 | O37: 0 | P37: 0 | Q37: =SUM(B37:P37) -> -4553.36 | T37: =SUM(B37:P37) -> -4553.36 | V37: =Q37-T37 -> 0 | X37: =Q37-C37-B37 -> -2702.12
A38: Vale Transporte e Condução - 321 | B38: -6096.88 | C38: -7130 | D38: -22363.09 | E38: -2934.44 | F38: -2679.63 | G38: -3062.45 | H38: -2516.68 | I38: -3016.06 | J38: -1228.06 | K38: 0 | L38: 0 | M38: 0 | N38: 0 | O38: 0 | P38: 0 | Q38: =SUM(B38:P38) -> -51027.29 | T38: =SUM(B38:P38) -> -51027.29 | V38: =Q38-T38 -> 0 | X38: =Q38-C38-B38 -> -37800.41
A39: Provisão 13º Salario - 314 | B39: -5681.26 | C39: -6444.74 | D39: -26689.52 | E39: -3168.53 | F39: -2672.17 | G39: -2672.17 | H39: -2718.45 | I39: -1924.49 | J39: -2197.62 | K39: 0 | L39: 0 | M39: 0 | N39: 0 | O39: 0 | P39: 0 | Q39: =SUM(B39:P39) -> -54168.95 | T39: =SUM(B39:P39) -> -54168.95 | V39: =Q39-T39 -> 0 | X39: =Q39-C39-B39 -> -42042.95
A40: Cursos e treinamentos - 849 | B40: 0 | C40: =SUM(E40:P40) -> 0 | D40: 0 | E40: 0 | F40: 0 | G40: 0 | H40: 0 | I40: 0 | J40: 0 | K40: 0 | L40: 0 | M40: 0 | N40: 0 | O40: 0 | P40: 0 | Q40: =SUM(B40:P40) -> 0 | T40: =SUM(B40:P40) -> 0 | V40: =Q40-T40 -> 0 | X40: =Q40-C40-B40 -> 0
A41: Confraternização de Funcionários | B41: 0 | C41: =SUM(E41:P41) -> 0 | D41: 0 | E41: 0 | F41: 0 | G41: 0 | H41: 0 | I41: 0 | J41: 0 | K41: 0 | L41: 0 | M41: 0 | N41: 0 | O41: 0 | P41: 0 | Q41: =SUM(B41:P41) -> 0 | T41: =SUM(B41:P41) -> 0 | V41: =Q41-T41 -> 0 | X41: =Q41-C41-B41 -> 0
A42: Custos Total... | B42: =SUM(B16:B41) -> -124569.51 | C42: =SUM(C16:C41) -> -121536.09 | D42: =SUM(D16:D41) -> -780756.74 | E42: =SUM(E16:E41) -> -84314.12 | F42: =SUM(F16:F41) -> -86150.56 | G42: =SUM(G16:G41) -> -88975.15 | H42: =SUM(H16:H41) -> -74103.89 | I42: =SUM(I16:I41) -> -51720.06 | ... Q42: =SUM(Q16:Q41) -> -1468419.6 | T42: =SUM(B42:P42) -> -1468419.6 | V42: =Q42-T42 -> 0 | X42: =Q42-C42-B42 -> -1222314
T43: =SUM(B43:P43) -> 0 | V43: =Q43-T43 -> 0
A44: = Lucro/Prejuízo Bruto | B44: =B13+B42 -> -124569.51 | C44: =C13+C42 -> -121536.09 | D44: =D13+D42 -> -780756.74 | E44: =E13+E42 -> -84314.12 | F44: =F13+F42 -> -86150.56 | G44: =G13+G42 -> -88975.15 | H44: =H13+H42 -> -74103.89 | I44: =I13+I42 -> -51720.06 | ... P44: =P13+P42 -> 0 | Q44: =SUM(B44:P44) -> -1468419.6 | T44: =SUM(B44:P44) -> -1468419.6 | V44: =Q44-T44 -> 0 | X44: =Q44-C44-B44 -> -1222314
...

Sheet OBRA 259 
A1: DEMONSTRAÇÃO DO RESULTADO APURADO
A3: OBRA 259 - ORION PATRIANI - PATRIANI
A5: OBRA ENCERRADA
B8: BOA NOVA | C8: BELA NOVA
B9: Jan a Fev/2022 | C9: Set a Dez/2021 | D9: Jan a Dez/2022 | E9: Jan a Dez/2023 | F9: Janeiro/2024 | G9: Fevereiro/2024 | H9: Março/2024 | I9: Abril/2024 | J9: Maio/2024 | K9: Junho/2024 | L9: Julho/2024 | M9: Agosto/2024 | N9: Setembro/2024 | O9: Outubro/2024 | P9: Novembro/2024 | Q9: Dezembro/2024 | R9: Acumulado | S9: % S/FAT
A10: Receitas Brutas
A11: Servicos prestados | B11: 0 | C11: 246533.35 | D11: =1431743.02-B11-C11 -> 1185209.7 | E11: =2893772.95-B11-C11-D11 -> 1462029.9 | F11: 0 | G11: 0 | H11: 0 | I11: 0 | J11: 0 | K11: 0 | L11: 0 | M11: 0 | N11: 0 | O11: 0 | P11: 0 | Q11: 0 | R11: =B11+C11+D11+E11+F11+G11+H11+I11+J11+K11+L11+M11+N11+O11+P11+Q11 -> 2893773 | S11: =R11/R13 -> 0.99522701 | U11: =SUM(B11:Q11) -> 2893773 | V11: =U11-R11 -> 0
A12: Locação de Equipamentos - 450 | B12: 0 | C12: 13878.18 | D12: =13878.18-B12-C12 -> 0 | E12: =13878.18-C12 -> 0 | F12: 0 | G12: 0 | H12: 0 | I12: 0 | J12: 0 | K12: 0 | L12: 0 | M12: 0 | N12: 0 | O12: 0 | P12: 0 | Q12: 0 | R12: =B12+C12+D12+E12+F12+G12+H12+I12+J12+K12+L12+M12+N12+O12+P12+Q12 -> 13878.18 | S12: =R12/R13 -> 0.0047729866 | U12: =SUM(B12:Q12) -> 13878.18 | V12: =U12-R12 -> 0
A13: Receitas Brutas Total... | B13: =B11+B12 -> 0 | C13: =C11+C12 -> 260411.53 | D13: =D11+D12 -> 1185209.7 | E13: =E11+E12 -> 1462029.9 | G13: =G11+G12 -> 0 | H13: =H11 -> 0 | I13: =I11 -> 0 | J13: =J11 -> 0 | K13: =K11 -> 0 | L13: =L11 -> 0 | M13: =M11 -> 0 | N13: =N11 -> 0 | O13: =O11 -> 0 | ... Q13: =Q11 -> 0 | R13: =SUM(R11:R12) -> 2907651.1 | S13: =SUM(S11:S12) -> 1 | U13: =SUM(B13:Q13) -> 2907651.1 | V13: =U13-R13 -> 0
U14: =SUM(B14:Q14) -> 0 | V14: =U14-R14 -> 0
A15: Custos | U15: =SUM(B15:Q15) -> 0 | V15: =U15-R15 -> 0
A16: Alimentação - 320 | B16: =15.07-287.72 -> -272.65 | C16: -3147.8 | D16: =-84418.97-B16-C16 -> -80998.52 | E16: =-190214.4-B16-C16-D16 -> -105795.43 | F16: 0 | G16: 0 | H16: 0 | I16: 0 | J16: 0 | K16: 0 | L16: 0 | M16: 0 | N16: 0 | O16: 0 | P16: 0 | Q16: 0 | R16: =B16+C16+D16+E16+F16+G16+H16+I16+J16+K16+L16+M16+N16+O16+P16+Q16 -> -190214.4 | S16: =-R16/$R$13 -> 0.065418577 | U16: =SUM(B16:Q16) -> -190214.4 | V16: =U16-R16 -> 0
A17: Combustíveis - 322 | B17: 0 | C17: 0 | D17: =-4053.88-B17-C17 -> -4053.88 | E17: =-4053.88-B17-C17-D17 -> 0 | F17: 0 | G17: 0 | H17: 0 | I17: 0 | J17: 0 | K17: 0 | L17: 0 | M17: 0 | N17: 0 | O17: 0 | P17: 0 | Q17: 0 | R17: =B17+C17+D17+E17+F17+G17+H17+I17+J17+K17+L17+M17+N17+O17+P17+Q17 -> -4053.88 | S17: =-R17/$R$13 -> 0.0013942113 | U17: =SUM(B17:Q17) -> -4053.88 | V17: =U17-R17 -> 0
A18: Despesa com Radio e Telefonia Celular | B18: 0 | C18: 0 | D18: =-1094-B18-C18 -> -1094 | E18: =-2174-B18-C18-D18 -> -1080 | F18: 0 | G18: 0 | H18: 0 | I18: 0 | J18: 0 | K18: 0 | L18: 0 | M18: 0 | N18: 0 | O18: 0 | P18: 0 | Q18: 0 | R18: =B18+C18+D18+E18+F18+G18+H18+I18+J18+K18+L18+M18+N18+O18+P18+Q18 -> -2174 | S18: =-R18/$R$13 -> 0.00074768255 | U18: =SUM(B18:Q18) -> -2174 | V18: =U18-R18 -> 0
A19: Equipamento de Segurança - EPIs - 360 | B19: 0 | C19: -3467.31 | D19: =-8069.23-B19-C19 -> -4601.92 | E19: =-10788.86-B19-C19-D19 -> -2719.63 | F19: 0 | G19: 0 | H19: 0 | I19: 0 | J19: 0 | K19: 0 | L19: 0 | M19: 0 | N19: 0 | O19: 0 | P19: 0 | Q19: 0 | R19: =B19+C19+D19+E19+F19+G19+H19+I19+J19+K19+L19+M19+N19+O19+P19+Q19 -> -10788.86 | S19: =-R19/$R$13 -> 0.003710507 | U19: =SUM(B19:Q19) -> -10788.86 | V19: =U19-R19 -> 0
A20: Ferias - 315 | B20: =-263.47-696.64 -> -960.11 | C20: -4277.4 | D20: =-54093.61-B20-C20 -> -48856.1 | E20: =-102612.88-B20-C20-D20 -> -48519.27 | F20: 0 | G20: 0 | H20: 0 | I20: 0 | J20: 0 | K20: 0 | L20: 0 | M20: 0 | N20: 0 | O20: 0 | P20: 0 | Q20: 0 | R20: =B20+C20+D20+E20+F20+G20+H20+I20+J20+K20+L20+M20+N20+O20+P20+Q20 -> -102612.88 | S20: =-R20/$R$13 -> 0.035290644 | U20: =SUM(B20:Q20) -> -102612.88 | V20: =U20-R20 -> 0
A21: FGTS - 317 | B21: =-162.42-460.3 -> -622.72 | C21: -1064 | D21: =-29386.17-B21-C21 -> -27699.45 | E21: =-60590.37-B21-C21-D21 -> -31204.2 | F21: 0 | G21: 0 | H21: 0 | I21: 0 | J21: 0 | K21: 0 | L21: 0 | M21: 0 | N21: 0 | O21: 0 | P21: 0 | Q21: 0 | R21: =B21+C21+D21+E21+F21+G21+H21+I21+J21+K21+L21+M21+N21+O21+P21+Q21 -> -60590.37 | S21: =-R21/$R$13 -> 0.020838253 | U21: =SUM(B21:Q21) -> -60590.37 | V21: =U21-R21 -> 0
A22: Horas Extras - 499 | B22: -632.27 | C22: 0 | D22: =-19127.09-B22-C22 -> -18494.82 | E22: =-41851.18-B22-C22-D22 -> -22724.09 | F22: 0 | G22: 0 | H22: 0 | I22: 0 | J22: 0 | K22: 0 | L22: 0 | M22: 0 | N22: 0 | O22: 0 | P22: 0 | Q22: 0 | R22: =B22+C22+D22+E22+F22+G22+H22+I22+J22+K22+L22+M22+N22+O22+P22+Q22 -> -41851.18 | S22: =-R22/$R$13 -> 0.014393467 | U22: =SUM(B22:Q22) -> -41851.18 | V22: =U22-R22 -> 0
A23: Indenizações e Aviso Prévio - 318 | B23: 0 | C23: 0 | D23: =2189.52-B23-C23 -> 2189.52 | E23: =2866.52-B23-C23-D23 -> 677 | F23: 0 | G23: 0 | H23: 0 | I23: 0 | J23: 0 | K23: 0 | L23: 0 | M23: 0 | N23: 0 | O23: 0 | P23: 0 | Q23: 0 | R23: =B23+C23+D23+E23+F23+G23+H23+I23+J23+K23+L23+M23+N23+O23+P23+Q23 -> 2866.52 | S23: =R23/$R$13 -> 0.00098585417 | U23: =SUM(B23:Q23) -> 2866.52 | V23: =U23-R23 -> 0
A24: Indenizações Trabalhistas Judiciais - 369 | B24: 0 | C24: 0 | D24: =0-B24-C24 -> 0 | E24: =0-B24-C24-D24 -> 0 | F24: 0 | G24: 0 | H24: 0 | I24: 0 | J24: 0 | K24: 0 | L24: 0 | M24: 0 | N24: 0 | O24: 0 | P24: 0 | Q24: 0 | R24: =B24+C24+D24+E24+F24+G24+H24+I24+J24+K24+L24+M24+N24+O24+P24+Q24 -> 0 | S24: =R24/$R$13 -> 0 | U24: =SUM(B24:Q24) -> 0 | V24: =U24-R24 -> 0
A25: INSS - 316 | B25: =-176.19-555.14 -> -731.33 | C25: -1730.4 | D25: =-35654.44-B25-C25 -> -33192.71 | E25: =-70619.5-B25-C25-D25 -> -34965.06 | F25: 0 | G25: 0 | H25: 0 | I25: 0 | J25: 0 | K25: 0 | L25: 0 | M25: 0 | N25: 0 | O25: 0 | P25: 0 | Q25: 0 | R25: =B25+C25+D25+E25+F25+G25+H25+I25+J25+K25+L25+M25+N25+O25+P25+Q25 -> -70619.5 | S25: =-R25/$R$13 -> 0.024287474 | U25: =SUM(B25:Q25) -> -70619.5 | V25: =U25-R25 -> 0
A26: Locação de Andaimes - 328 | B26: 0 | C26: 0 | D26: =-2889-B26-C26 -> -2889 | E26: =-7329-B26-C26-D26 -> -4440 | F26: 0 | G26: 0 | H26: 0 | I26: 0 | J26: 0 | K26: 0 | L26: 0 | M26: 0 | N26: 0 | O26: 0 | P26: 0 | Q26: 0 | R26: =B26+C26+D26+E26+F26+G26+H26+I26+J26+K26+L26+M26+N26+O26+P26+Q26 -> -7329 | S26: =-R26/$R$13 -> 0.0025205913 | U26: =SUM(B26:Q26) -> -7329 | V26: =U26-R26 -> 0
A27: Locação de Máqs, Ferramentas e Equipamentos - | B27: 0 | C27: 0 | D27: =-14203.89-B27-C27 -> -14203.89 | E27: =-33430.49-B27-C27-D27 -> -19226.6 | F27: 0 | G27: 0 | H27: 0 | I27: 0 | J27: 0 | K27: 0 | L27: 0 | M27: 0 | N27: 0 | O27: 0 | P27: 0 | Q27: 0 | R27: =B27+C27+D27+E27+F27+G27+H27+I27+J27+K27+L27+M27+N27+O27+P27+Q27 -> -33430.49 | S27: =-R27/$R$13 -> 0.011497421 | U27: =SUM(B27:Q27) -> -33430.49 | V27: =U27-R27 -> 0
A28: Manutenção de Equipamento - 394 | B28: =-42.42-69.23 -> -111.65 | C28: 0 | D28: =-111.65-B28-C28 -> 0 | E28: =-111.65-B28-C28-D28 -> 0 | F28: 0 | G28: 0 | H28: 0 | I28: 0 | J28: 0 | K28: 0 | L28: 0 | M28: 0 | N28: 0 | O28: 0 | P28: 0 | Q28: 0 | R28: =B28+C28+D28+E28+F28+G28+H28+I28+J28+K28+L28+M28+N28+O28+P28+Q28 -> -111.65 | S28: =-R28/$R$13 -> 3.8398692e-05 | U28: =SUM(B28:Q28) -> -111.65 | V28: =U28-R28 -> 0
A29: Manutenção de Veículos - 510 | B29: 0 | C29: 0 | D29: =-220-B29-C29 -> -220 | E29: =-220-B29-C29-D29 -> 0 | F29: 0 | G29: 0 | H29: 0 | I29: 0 | J29: 0 | K29: 0 | L29: 0 | M29: 0 | N29: 0 | O29: 0 | P29: 0 | Q29: 0 | R29: =B29+C29+D29+E29+F29+G29+H29+I29+J29+K29+L29+M29+N29+O29+P29+Q29 -> -220 | S29: =-R29/$R$13 -> 7.5662447e-05 | U29: =SUM(B29:Q29) -> -220 | V29: =U29-R29 -> 0
A30: Medicina Ocupacional e Assist médica - 3 | B30: 0 | C30: 0 | D30: =-4553.96-B30-C30 -> -4553.96 | E30: =-7000.4-B30-C30-D30 -> -2446.44 | F30: 0 | G30: 0 | H30: 0 | I30: 0 | J30: 0 | K30: 0 | L30: 0 | M30: 0 | N30: 0 | O30: 0 | P30: 0 | Q30: 0 | R30: =B30+C30+D30+E30+F30+G30+H30+I30+J30+K30+L30+M30+N30+O30+P30+Q30 -> -7000.4 | S30: =-R30/$R$13 -> 0.0024075791 | U30: =SUM(B30:Q30) -> -7000.4 | V30: =U30-R30 -> 0
A31: Móveis Não Imobilizado - 364 | B31: 0 | C31: 0 | D31: =-1700-B31-C31 -> -1700 | E31: =-1700-B31-C31-D31 -> 0 | F31: 0 | G31: 0 | H31: 0 | I31: 0 | J31: 0 | K31: 0 | L31: 0 | M31: 0 | N31: 0 | O31: 0 | P31: 0 | Q31: 0 | R31: =B31+C31+D31+E31+F31+G31+H31+I31+J31+K31+L31+M31+N31+O31+P31+Q31 -> -1700 | S31: =-R31/$R$13 -> 0.00058466436 | U31: =SUM(B31:Q31) -> -1700 | V31: =U31-R31 -> 0
A32: Peças, Ferramentas e Acessórios - 361 | B32: 0 | C32: -9447.04 | D32: =-31028.35-B32-C32 -> -21581.31 | E32: =-31119.46-B32-C32-D32 -> -91.11 | F32: 0 | G32: 0 | H32: 0 | I32: 0 | J32: 0 | K32: 0 | L32: 0 | M32: 0 | N32: 0 | O32: 0 | P32: 0 | Q32: 0 | R32: =B32+C32+D32+E32+F32+G32+H32+I32+J32+K32+L32+M32+N32+O32+P32+Q32 -> -31119.46 | S32: =-R32/$R$13 -> 0.010702611 | U32: =SUM(B32:Q32) -> -31119.46 | V32: =U32-R32 -> 0
A33: Premios e Gratificacoes - 313 | B33: =-1301-1682 -> -2983 | C33: -1644 | D33: =-164963.45-B33-C33 -> -160336.45 | E33: =-346100.83-B33-C33-D33 -> -181137.38 | F33: 0 | G33: 0 | H33: 0 | I33: 0 | J33: 0 | K33: 0 | L33: 0 | M33: 0 | N33: 0 | O33: 0 | P33: 0 | Q33: 0 | R33: =B33+C33+D33+E33+F33+G33+H33+I33+J33+K33+L33+M33+N33+O33+P33+Q33 -> -346100.83 | S33: =-R33/$R$13 -> 0.11903107 | U33: =SUM(B33:Q33) -> -346100.83 | V33: =U33-R33 -> 0
A34: Salarios e Ordenados - 311 | B34: =-2028.78-5591.34 -> -7620.12 | C34: -13299.43 | D34: =-357928.53-B34-C34 -> -337008.98 | E34: =-706283.73-B34-C34-D34 -> -348355.2 | F34: 0 | G34: 0 | H34: 0 | I34: 0 | J34: 0 | K34: 0 | L34: 0 | M34: 0 | N34: 0 | O34: 0 | P34: 0 | Q34: 0 | R34: =B34+C34+D34+E34+F34+G34+H34+I34+J34+K34+L34+M34+N34+O34+P34+Q34 -> -706283.73 | S34: =-R34/$R$13 -> 0.24290525 | U34: =SUM(B34:Q34) -> -706283.73 | V34: =U34-R34 -> 0
A35: Serviços de Terceiros - 324 | B35: -300 | C35: 0 | D35: =-364.5-B35-C35 -> -64.5 | E35: =-437.3-B35-C35-D35 -> -72.8 | F35: 0 | G35: 0 | H35: 0 | I35: 0 | J35: 0 | K35: 0 | L35: 0 | M35: 0 | N35: 0 | O35: 0 | P35: 0 | Q35: 0 | R35: =B35+C35+D35+E35+F35+G35+H35+I35+J35+K35+L35+M35+N35+O35+P35+Q35 -> -437.3 | S35: =-R35/$R$13 -> 0.00015039631 | U35: =SUM(B35:Q35) -> -437.3 | V35: =U35-R35 -> 0
A36: Seguro Riscos Execução de Serv. Trab. | B36: 0 | C36: 0 | D36: =0-B36-C36 -> 0 | E36: =0-B36-C36-D36 -> 0 | F36: 0 | G36: 0 | H36: 0 | I36: 0 | J36: 0 | K36: 0 | L36: 0 | M36: 0 | N36: 0 | O36: 0 | P36: 0 | Q36: 0 | R36: =B36+C36+D36+E36+F36+G36+H36+I36+J36+K36+L36+M36+N36+O36+P36+Q36 -> 0 | S36: =R36/$R$13 -> 0 | U36: =SUM(B36:Q36) -> 0 | V36: =U36-R36 -> 0
A37: Uniformes - 425 | B37: 0 | C37: -3442 | D37: =-6568.64-B37-C37 -> -3126.64 | E37: =-10452.41-B37-C37-D37 -> -3883.77 | F37: 0 | G37: 0 | H37: 0 | I37: 0 | J37: 0 | K37: 0 | L37: 0 | M37: 0 | N37: 0 | O37: 0 | P37: 0 | Q37: 0 | R37: =B37+C37+D37+E37+F37+G37+H37+I37+J37+K37+L37+M37+N37+O37+P37+Q37 -> -10452.41 | S37: =-R37/$R$13 -> 0.0035947951 | U37: =SUM(B37:Q37) -> -10452.41 | V37: =U37-R37 -> 0
A38: Vale Transporte e Condução - 321 | B38: =121.81+183.78 -> 305.59 | C38: 156.6 | D38: =-28488.44-B38-C38 -> -28950.63 | E38: =-67336.36-B38-C38-D38 -> -38847.92 | F38: 0 | G38: 0 | H38: 0 | I38: 0 | J38: 0 | K38: 0 | L38: 0 | M38: 0 | N38: 0 | O38: 0 | P38: 0 | Q38: 0 | R38: =B38+C38+D38+E38+F38+G38+H38+I38+J38+K38+L38+M38+N38+O38+P38+Q38 -> -67336.36 | S38: =-R38/$R$13 -> 0.023158335 | U38: =SUM(B38:Q38) -> -67336.36 | V38: =U38-R38 -> 0
A39: 13º Salario - 314 | B39: =-197.61-522.48 -> -720.09 | C39: -3174.64 | D39: =-38780.29-B39-C39 -> -34885.56 | E39: =-74177.15-B39-C39-D39 -> -35396.86 | F39: 0 | G39: 0 | H39: 0 | I39: 0 | J39: 0 | K39: 0 | L39: 0 | M39: 0 | N39: 0 | O39: 0 | P39: 0 | Q39: 0 | R39: =B39+C39+D39+E39+F39+G39+H39+I39+J39+K39+L39+M39+N39+O39+P39+Q39 -> -74177.15 | S39: =-R39/$R$13 -> 0.025511021 | U39: =SUM(B39:Q39) -> -74177.15 | V39: =U39-R39 -> 0
A40: Cursos e treinamentos | B40: 0 | C40: 0 | D40: 0 | E40: 0 | F40: 0 | G40: 0 | H40: 0 | I40: 0 | J40: 0 | K40: 0 | L40: 0 | M40: 0 | N40: 0 | O40: 0 | P40: 0 | Q40: 0 | R40: =B40+C40+D40+E40+F40+G40+H40+I40+J40+K40+L40+M40+N40+O40+P40+Q40 -> 0 | S40: =-R40/$R$13 -> 0 | U40: =SUM(B40:Q40) -> 0 | V40: =U40-R40 -> 0
A41: Confraternização de Funcionários | B41: 0 | C41: 0 | D41: 0 | E41: 0 | F41: 0 | G41: 0 | H41: 0 | I41: 0 | J41: 0 | K41: 0 | L41: 0 | M41: 0 | N41: 0 | O41: 0 | P41: 0 | Q41: 0 | R41: =B41+C41+D41+E41+F41+G41+H41+I41+J41+K41+L41+M41+N41+O41+P41+Q41 -> 0 | U41: =SUM(B41:Q41) -> 0 | V41: =U41-R41 -> 0
A42: Custos Total... | B42: =SUM(B16:B41) -> -14648.35 | C42: =SUM(C16:C41) -> -44537.42 | D42: =SUM(D16:D41) -> -826322.8 | E42: =SUM(E16:E41) -> -880228.76 | F42: =SUM(F16:F41) -> 0 | G42: =SUM(G16:G41) -> 0 | H42: =SUM(H16:H41) -> 0 | I42: =SUM(I16:I41) -> 0 | ... R42: =SUM(R16:R41) -> -1765737.3 | S42: =-R42/$R$13 -> 0.60727276 | U42: =SUM(B42:Q42) -> -1765737.3 | V42: =U42-R42 -> 0
U43: =SUM(B43:Q43) -> 0 | V43: =U43-R43 -> 0
A44: = Lucro/Prejuízo Bruto | B44: =B13+B42 -> -14648.35 | C44: =C13+C42 -> 215874.11 | D44: =D13+D42 -> 358886.87 | E44: =E13+E42 -> 581801.17 | F44: =F13+F42 -> 0 | G44: =G13+G42 -> 0 | H44: =H13+H42 -> 0 | I44: =I13+I42 -> 0 | ... Q44: =Q13+Q42 -> 0 | R44: =B44+C44+D44+E44+F44+G44+H44+I44+J44+K44+L44+M44+N44+O44+P44+Q44 -> 1141913.8 | S44: =R44/$R$13 -> 0.39272724 | U44: =SUM(B44:Q44) -> 1141913.8 | V44: =U44-R44 -> 0
...

Sheet OBRA 265
A1: BELA NOVA CONSTRUTORA LTDA
A3: DEMONSTRAÇÃO DO RESULTADO APURADO
A5: OBRA 265 - EPIC - PATRIANI
A7: OBRA ENCERRADA
B10: Abr a Dez/2022 | C10: Jan a Dez/2023 | D10: Janeiro/2024 | E10: Fevereiro/2024 | F10: Março/2024 | G10: Abril/2024 | H10: Maio/2024 | I10: Junho/2024 | J10: Julho/2024 | K10: Agosto/2024 | L10: Setembro/2024 | M10: Outubro/2024 | N10: Novembro/2024 | O10: Dezembro/2024 | P10: Acumulado | Q10: % S/FAT
A11: Receitas Brutas
A12: Servicos prestados | B12: 1073054.4 | C12: =3039481.55-B12 -> 1966427.2 | D12: 0 | E12: 49000 | F12: 0 | G12: 123252.53 | H12: 0 | I12: 0 | J12: 0 | K12: 0 | L12: 0 | M12: 0 | N12: 0 | O12: 0 | P12: =B12+C12+D12+E12+F12+G12+H12+I12+J12+K12+L12+M12+N12+O12 -> 3211734.1 | Q12: 1 | S12: =SUM(B12:H12) -> 3211734.1 | U12: =S12-P12 -> 0
A13: Locação de Equipamentos - 450 | B13: 0 | C13: 0 | D13: 0 | E13: 0 | F13: 0 | G13: 0 | H13: 0 | I13: 0 | J13: 0 | K13: 0 | L13: 0 | M13: 0 | N13: 0 | O13: 0 | P13: =B13+C13+D13+E13+F13+G13+H13+I13+J13+K13+L13+M13+N13+O13 -> 0 | S13: =SUM(B13:H13) -> 0 | U13: =S13-P13 -> 0
A14: Receitas Brutas Total... | B14: =B12+B13 -> 1073054.4 | C14: =C12+C13 -> 1966427.2 | D14: =D12+D13 -> 0 | E14: =E12+E13 -> 49000 | F14: =F12 -> 0 | G14: =G12 -> 123252.53 | H14: =H12 -> 0 | I14: =I12 -> 0 | J14: =J12 -> 0 | K14: =K12 -> 0 | L14: =L12 -> 0 | M14: =M12 -> 0 | ... O14: =O12 -> 0 | P14: =SUM(P12:P13) -> 3211734.1 | Q14: 1 | S14: =SUM(B14:H14) -> 3211734.1 | U14: =S14-P14 -> 0
S15: =SUM(B15:H15) -> 0 | U15: =S15-P15 -> 0
A16: Custos | S16: =SUM(B16:H16) -> 0 | U16: =S16-P16 -> 0
A17: Alimentação - 320 | B17: -58280.6 | C17: =-163575.93-B17 -> -105295.33 | D17: -2407.65 | E17: 30.14 | F17: 15.07 | G17: 15.07 | H17: 0 | I17: 0 | J17: 0 | K17: 0 | L17: 0 | M17: 0 | N17: 0 | O17: 0 | P17: =B17+C17+D17+E17+F17+G17+H17+I17+J17+K17+L17+M17+N17+O17 -> -165923.3 | Q17: =-P17/$P$14 -> 0.051661593 | S17: =SUM(B17:H17) -> -165923.3 | U17: =S17-P17 -> 0
A18: Combustíveis - 322 | B18: -3576.92 | C18: =-3576.92-B18 -> 0 | D18: 0 | E18: 0 | F18: 0 | G18: 0 | H18: 0 | I18: 0 | J18: 0 | K18: 0 | L18: 0 | M18: 0 | N18: 0 | O18: 0 | P18: =B18+C18+D18+E18+F18+G18+H18+I18+J18+K18+L18+M18+N18+O18 -> -3576.92 | Q18: =-P18/$P$14 -> 0.0011137037 | S18: =SUM(B18:H18) -> -3576.92 | U18: =S18-P18 -> 0
A19: Despesa com Radio e Telefonia Celular | B19: -646 | C19: =-1726-B19 -> -1080 | D19: 0 | E19: 0 | F19: 0 | G19: 0 | H19: 0 | I19: 0 | J19: 0 | K19: 0 | L19: 0 | M19: 0 | N19: 0 | O19: 0 | P19: =B19+C19+D19+E19+F19+G19+H19+I19+J19+K19+L19+M19+N19+O19 -> -1726 | Q19: =-P19/$P$14 -> 0.00053740439 | S19: =SUM(B19:H19) -> -1726 | U19: =S19-P19 -> 0
A20: Equipamento de Segurança - EPIs - 360 | B20: -3261.08 | C20: =-7389.99-B20 -> -4128.91 | D20: 0 | E20: 0 | F20: 0 | G20: 0 | H20: 0 | I20: 0 | J20: 0 | K20: 0 | L20: 0 | M20: 0 | N20: 0 | O20: 0 | P20: =B20+C20+D20+E20+F20+G20+H20+I20+J20+K20+L20+M20+N20+O20 -> -7389.99 | Q20: =-P20/$P$14 -> 0.0023009346 | S20: =SUM(B20:H20) -> -7389.99 | U20: =S20-P20 -> 0
A21: Ferias - 315 | B21: -37222.81 | C21: =-92794.88-B21 -> -55572.07 | D21: -624.25 | E21: -624.25 | F21: -312.12 | G21: 0 | H21: 0 | I21: 0 | J21: 0 | K21: 0 | L21: 0 | M21: 0 | N21: 0 | O21: 0 | P21: =B21+C21+D21+E21+F21+G21+H21+I21+J21+K21+L21+M21+N21+O21 -> -94355.5 | Q21: =-P21/$P$14 -> 0.029378366 | S21: =SUM(B21:H21) -> -94355.5 | U21: =S21-P21 -> 0
A22: FGTS - 317 | B22: -22076.8 | C22: =-58889.42-B22 -> -36812.62 | D22: -384.81 | E22: -384.81 | F22: -192.4 | G22: -192.4 | H22: -256.54 | I22: 0 | J22: 0 | K22: 0 | L22: 0 | M22: 0 | N22: 0 | O22: 0 | P22: =B22+C22+D22+E22+F22+G22+H22+I22+J22+K22+L22+M22+N22+O22 -> -60300.38 | Q22: =-P22/$P$14 -> 0.018775023 | S22: =SUM(B22:H22) -> -60300.38 | U22: =S22-P22 -> 0
A23: Horas Extras - 499 | B23: -15783.83 | C23: =-34957.72-B23 -> -19173.89 | D23: 0 | E23: 0 | F23: 0 | G23: 0 | H23: 0 | I23: 0 | J23: 0 | K23: 0 | L23: 0 | M23: 0 | N23: 0 | O23: 0 | P23: =B23+C23+D23+E23+F23+G23+H23+I23+J23+K23+L23+M23+N23+O23 -> -34957.72 | Q23: =-P23/$P$14 -> 0.010884376 | S23: =SUM(B23:H23) -> -34957.72 | U23: =S23-P23 -> 0
A24: Indenizações e Aviso Prévio - 318 | B24: 1520.02 | C24: =1520.02-B24 -> 0 | D24: 0 | E24: 0 | F24: 0 | G24: 0 | H24: 0 | I24: 0 | J24: 0 | K24: 0 | L24: 0 | M24: 0 | N24: 0 | O24: 0 | P24: =B24+C24+D24+E24+F24+G24+H24+I24+J24+K24+L24+M24+N24+O24 -> 1520.02 | Q24: =P24/$P$14 -> 0.00047327081 | S24: =SUM(B24:H24) -> 1520.02 | U24: =S24-P24 -> 0
A25: Indenizações Trabalhistas Judiciais - 369 | B25: 0 | C25: =0-B25 -> 0 | D25: 0 | E25: 0 | F25: 0 | G25: 0 | H25: 0 | I25: 0 | J25: 0 | K25: 0 | L25: 0 | M25: 0 | N25: 0 | O25: 0 | P25: =B25+C25+D25+E25+F25+G25+H25+I25+J25+K25+L25+M25+N25+O25 -> 0 | Q25: =P25/$P$14 -> 0 | S25: =SUM(B25:H25) -> 0 | U25: =S25-P25 -> 0
A26: INSS - 316 | B26: -27064.53 | C26: =-68169.57-B26 -> -41105.04 | D26: -423.29 | E26: -423.29 | F26: -211.65 | G26: -211.65 | H26: -282.19 | I26: 0 | J26: 0 | K26: 0 | L26: 0 | M26: 0 | N26: 0 | O26: 0 | P26: =B26+C26+D26+E26+F26+G26+H26+I26+J26+K26+L26+M26+N26+O26 -> -69721.64 | Q26: =-P26/$P$14 -> 0.02170841 | S26: =SUM(B26:H26) -> -69721.64 | U26: =S26-P26 -> 0
A27: Locação de Andaimes - 328 | B27: -2514.39 | C27: =-4779.39-B27 -> -2265 | D27: 0 | E27: 0 | F27: 0 | G27: 0 | H27: 0 | I27: 0 | J27: 0 | K27: 0 | L27: 0 | M27: 0 | N27: 0 | O27: 0 | P27: =B27+C27+D27+E27+F27+G27+H27+I27+J27+K27+L27+M27+N27+O27 -> -4779.39 | Q27: =-P27/$P$14 -> 0.0014881027 | S27: =SUM(B27:H27) -> -4779.39 | U27: =S27-P27 -> 0
A28: Locação de Máqs, Ferramentas e Equipamentos - | B28: -12475.82 | C28: =-40246.35-B28 -> -27770.53 | D28: 0 | E28: 0 | F28: 0 | G28: 0 | H28: 0 | I28: 0 | J28: 0 | K28: 0 | L28: 0 | M28: 0 | N28: 0 | O28: 0 | P28: =B28+C28+D28+E28+F28+G28+H28+I28+J28+K28+L28+M28+N28+O28 -> -40246.35 | Q28: =-P28/$P$14 -> 0.012531034 | S28: =SUM(B28:H28) -> -40246.35 | U28: =S28-P28 -> 0
A29: Manutenção de Equipamento - 394 | B29: 0 | C29: =0-B29 -> 0 | D29: 0 | E29: 0 | F29: 0 | G29: 0 | H29: 0 | I29: 0 | J29: 0 | K29: 0 | L29: 0 | M29: 0 | N29: 0 | O29: 0 | P29: =B29+C29+D29+E29+F29+G29+H29+I29+J29+K29+L29+M29+N29+O29 -> 0 | Q29: =-P29/$P$14 -> 0 | S29: =SUM(B29:H29) -> 0 | U29: =S29-P29 -> 0
A30: Manutenção de Veículos - 510 | B30: -220 | C30: =-220-B30 -> 0 | D30: 0 | E30: 0 | F30: 0 | G30: 0 | H30: 0 | I30: 0 | J30: 0 | K30: 0 | L30: 0 | M30: 0 | N30: 0 | O30: 0 | P30: =B30+C30+D30+E30+F30+G30+H30+I30+J30+K30+L30+M30+N30+O30 -> -220 | Q30: =-P30/$P$14 -> 6.8498822e-05 | S30: =SUM(B30:H30) -> -220 | U30: =S30-P30 -> 0
A31: Medicina Ocupacional e Assist médica - 3 | B31: -2718.34 | C31: =-5129.9-B31 -> -2411.56 | D31: 0 | E31: 0 | F31: 0 | G31: 0 | H31: 0 | I31: 0 | J31: 0 | K31: 0 | L31: 0 | M31: 0 | N31: 0 | O31: 0 | P31: =B31+C31+D31+E31+F31+G31+H31+I31+J31+K31+L31+M31+N31+O31 -> -5129.9 | Q31: =-P31/$P$14 -> 0.0015972368 | S31: =SUM(B31:H31) -> -5129.9 | U31: =S31-P31 -> 0
A32: Móveis Não Imobilizado - 364 | B32: 0 | C32: =0-B32 -> 0 | D32: 0 | E32: 0 | F32: 0 | G32: 0 | H32: 0 | I32: 0 | J32: 0 | K32: 0 | L32: 0 | M32: 0 | N32: 0 | O32: 0 | P32: =B32+C32+D32+E32+F32+G32+H32+I32+J32+K32+L32+M32+N32+O32 -> 0 | Q32: =P32/$P$14 -> 0 | S32: =SUM(B32:H32) -> 0 | U32: =S32-P32 -> 0
A33: Peças, Ferramentas e Acessórios - 361 | B33: -8145.26 | C33: =-8814.71-B33 -> -669.45 | D33: 0 | E33: 0 | F33: 0 | G33: 0 | H33: 0 | I33: 0 | J33: 0 | K33: 0 | L33: 0 | M33: 0 | N33: 0 | O33: 0 | P33: =B33+C33+D33+E33+F33+G33+H33+I33+J33+K33+L33+M33+N33+O33 -> -8814.71 | Q33: =-P33/$P$14 -> 0.0027445329 | S33: =SUM(B33:H33) -> -8814.71 | U33: =S33-P33 -> 0
A34: Premios e Gratificacoes - 313 | B34: -123190.74 | C34: =-301502.74-B34 -> -178312 | D34: -2590 | E34: -2638 | F34: -794 | G34: 0 | H34: 0 | I34: 0 | J34: 0 | K34: 0 | L34: 0 | M34: 0 | N34: 0 | O34: 0 | P34: =B34+C34+D34+E34+F34+G34+H34+I34+J34+K34+L34+M34+N34+O34 -> -307524.74 | Q34: =-P34/$P$14 -> 0.095750374 | S34: =SUM(B34:H34) -> -307524.74 | U34: =S34-P34 -> 0
A35: Salarios e Ordenados - 311 | B35: -270622.64 | C35: =-672681.71-B35 -> -402059.07 | D35: -4808.42 | E35: -4808.42 | F35: -2403.71 | G35: -2404.71 | H35: 0 | I35: 0 | J35: 0 | K35: 0 | L35: 0 | M35: 0 | N35: 0 | O35: 0 | P35: =B35+C35+D35+E35+F35+G35+H35+I35+J35+K35+L35+M35+N35+O35 -> -687106.97 | Q35: =-P35/$P$14 -> 0.21393644 | S35: =SUM(B35:H35) -> -687106.97 | U35: =S35-P35 -> 0
A36: Serviços de Terceiros - 324 | B36: -64.5 | C36: =-137.22-B36 -> -72.72 | D36: 0 | E36: 0 | F36: 0 | G36: 0 | H36: 0 | I36: 0 | J36: 0 | K36: 0 | L36: 0 | M36: 0 | N36: 0 | O36: 0 | P36: =B36+C36+D36+E36+F36+G36+H36+I36+J36+K36+L36+M36+N36+O36 -> -137.22 | Q36: =-P36/$P$14 -> 4.2724583e-05 | S36: =SUM(B36:H36) -> -137.22 | U36: =S36-P36 -> 0
A37: Seguro Riscos Execução de Serv. Trab. | B37: 0 | C37: =0-B37 -> 0 | D37: 0 | E37: 0 | F37: 0 | G37: 0 | H37: 0 | I37: 0 | J37: 0 | K37: 0 | L37: 0 | M37: 0 | N37: 0 | O37: 0 | P37: =B37+C37+D37+E37+F37+G37+H37+I37+J37+K37+L37+M37+N37+O37 -> 0 | Q37: =P37/$P$14 -> 0 | S37: =SUM(B37:H37) -> 0 | U37: =S37-P37 -> 0
A38: Uniformes - 425 | B38: -4838.47 | C38: =-10826.88-B38 -> -5988.41 | D38: 0 | E38: 0 | F38: 0 | G38: 0 | H38: 0 | I38: 0 | J38: 0 | K38: 0 | L38: 0 | M38: 0 | N38: 0 | O38: 0 | P38: =B38+C38+D38+E38+F38+G38+H38+I38+J38+K38+L38+M38+N38+O38 -> -10826.88 | Q38: =-P38/$P$14 -> 0.0033710387 | S38: =SUM(B38:H38) -> -10826.88 | U38: =S38-P38 -> 0
A39: Vale Transporte e Condução - 321 | B39: -22442.06 | C39: =-63211.64-B39 -> -40769.58 | D39: -643.9 | E39: -153 | F39: -258.9 | G39: -64.7 | H39: -199.5 | I39: 0 | J39: 0 | K39: 0 | L39: 0 | M39: 0 | N39: 0 | O39: 0 | P39: =B39+C39+D39+E39+F39+G39+H39+I39+J39+K39+L39+M39+N39+O39 -> -64531.64 | Q39: =-P39/$P$14 -> 0.02009246 | S39: =SUM(B39:H39) -> -64531.64 | U39: =S39-P39 -> 0
A40: 13º Salario - 314 | B40: -25007.33 | C40: =-65983.22-B40 -> -40975.89 | D40: -468.19 | E40: -468.19 | F40: -234.09 | G40: -234.09 | H40: 0 | I40: 0 | J40: 0 | K40: 0 | L40: 0 | M40: 0 | N40: 0 | O40: 0 | P40: =B40+C40+D40+E40+F40+G40+H40+I40+J40+K40+L40+M40+N40+O40 -> -67387.78 | Q40: =-P40/$P$14 -> 0.020981743 | S40: =SUM(B40:H40) -> -67387.78 | U40: =S40-P40 -> 0
A41: Cursos e treinamentos | B41: 0 | C41: =0-B41 -> 0 | D41: 0 | E41: 0 | F41: 0 | G41: 0 | H41: 0 | I41: 0 | J41: 0 | K41: 0 | L41: 0 | M41: 0 | N41: 0 | O41: 0 | P41: =B41+C41+D41+E41+F41+G41+H41+I41+J41+K41+L41+M41+N41+O41 -> 0 | Q41: =-P41/$P$14 -> 0 | S41: =SUM(B41:H41) -> 0 | U41: =S41-P41 -> 0
A42: Confraternização de Funcionários | B42: 0 | C42: 0 | D42: 0 | E42: 0 | F42: 0 | G42: 0 | H42: 0 | I42: 0 | J42: 0 | K42: 0 | L42: 0 | M42: 0 | N42: 0 | O42: 0 | P42: =B42+C42+D42+E42+F42+G42+H42+I42+J42+K42+L42+M42+N42+O42 -> 0 | Q42: =-P42/$P$14 -> 0 | S42: =SUM(B42:H42) -> 0 | U42: =S42-P42 -> 0
A43: Custos Total... | B43: =SUM(B17:B42) -> -638632.1 | C43: =SUM(C17:C42) -> -964462.07 | D43: =SUM(D17:D42) -> -12350.51 | E43: =SUM(E17:E42) -> -9469.82 | F43: =SUM(F17:F42) -> -4391.8 | G43: =SUM(G17:G42) -> -3092.48 | H43: =SUM(H17:H42) -> -738.23 | I43: =SUM(I17:I42) -> 0 | ... P43: =SUM(P17:P42) -> -1633137 | Q43: =-P43/$P$14 -> 0.50849073 | S43: =SUM(B43:H43) -> -1633137 | U43: =S43-P43 -> 0
S44: =SUM(B44:H44) -> 0 | U44: =S44-P44 -> 0
A45: = Lucro/Prejuízo Bruto | B45: =B14+B43 -> 434422.26 | C45: =C14+C43 -> 1001965.1 | D45: =D14+D43 -> -12350.51 | E45: =E14+E43 -> 39530.18 | F45: =F14+F43 -> -4391.8 | G45: =G14+G43 -> 120160.05 | H45: =H14+H43 -> -738.23 | I45: =I14+I43 -> 0 | ... O45: =O14+O43 -> 0 | P45: =B45+C45+D45+E45+F45+G45+H45+I45+J45+K45+L45+M45+N45+O45 -> 1578597.1 | Q45: =P45/$P$14 -> 0.49150927 | S45: =SUM(B45:H45) -> 1578597.1 | U45: =S45-P45 -> 0
...

Sheet OBRA 267
A1: BELA NOVA CONSTRUTORA EIRELI
A4: DEMONSTRAÇÃO DO RESULTADO APURADO
A6: OBRA 267 - SIGNATURE - EZTEC
A8: OBRA ENCERRADA
B10: Out a Dez/2022 | C10: Jan a Dez/2023 | D10: Jan a Dez/2024 | E10: Janeiro/2025 | F10: Fevereiro/2025 | G10: Março/2025 | H10: Abril/2025 | I10: Maio/2025 | J10: Junho/2025 | K10: Julho/2025 | L10: Agosto/2025 | M10: Setembro/2025 | N10: Outubro/2025 | O10: Novembro/2025 | P10: Dezembro/2025 | Q10: Acumulado | R10: % S/FAT
A11: Receitas Brutas
A12: Servicos prestados | B12: 0 | C12: 1032969.5 | D12: 104718.58 | E12: 0 | F12: 0 | G12: 0 | H12: 0 | I12: 0 | J12: 0 | K12: 0 | L12: 0 | M12: 0 | N12: 0 | O12: 0 | P12: 0 | Q12: =B12+C12+D12+E12+F12+G12+H12+I12+J12+K12+L12+M12+N12+O12+P12 -> 1137688.1 | R12: 1 | T12: =SUM(B12:P12) -> 1137688.1 | V12: =T12-Q12 -> 0
A13: Locação de Equipamentos - 450 | B13: 0 | C13: 0 | D13: =SUM(E13:P13) -> 0 | E13: 0 | F13: 0 | G13: 0 | H13: 0 | I13: 0 | J13: 0 | K13: 0 | L13: 0 | M13: 0 | N13: 0 | O13: 0 | P13: 0 | Q13: =B13+C13+D13+E13+F13+G13+H13+I13+J13+K13+L13+M13+N13+O13+P13 -> 0 | T13: =SUM(B13:P13) -> 0 | V13: =T13-Q13 -> 0
A14: Receitas Brutas Total... | B14: =B12+B13 -> 0 | C14: =C12+C13 -> 1032969.5 | D14: =SUM(D12:D13) -> 104718.58 | E14: =E12+E13 -> 0 | F14: =F12+F13 -> 0 | G14: =G12 -> 0 | H14: =H12 -> 0 | I14: =I12 -> 0 | J14: =J12 -> 0 | K14: =K12 -> 0 | L14: =L12 -> 0 | M14: =M12 -> 0 | N14: =N12 -> 0 | ... P14: =P12 -> 0 | Q14: =SUM(Q12:Q13) -> 1137688.1 | R14: 1 | T14: =SUM(B14:P14) -> 1137688.1 | V14: =T14-Q14 -> 0
T15: =SUM(B15:P15) -> 0
A16: Custos | T16: =SUM(B16:P16) -> 0
A17: Alimentação - 320 | B17: -6869.47 | C17: =-79288.13-B17 -> -72418.66 | D17: -24315.58 | E17: 0 | F17: 0 | G17: 0 | H17: 0 | I17: 0 | J17: 0 | K17: 0 | L17: 0 | M17: 0 | N17: 0 | O17: 0 | P17: 0 | Q17: =B17+C17+D17+E17+F17+G17+H17+I17+J17+K17+L17+M17+N17+O17+P17 -> -103603.71 | R17: =-Q17/$Q$14 -> 0.091065129 | T17: =SUM(B17:P17) -> -103603.71 | V17: =T17-Q17 -> 0
A18: Combustíveis - 322 | B18: -176.92 | C18: =-176.92-B18 -> 0 | D18: 0 | E18: 0 | F18: 0 | G18: 0 | H18: 0 | I18: 0 | J18: 0 | K18: 0 | L18: 0 | M18: 0 | N18: 0 | O18: 0 | P18: 0 | Q18: =B18+C18+D18+E18+F18+G18+H18+I18+J18+K18+L18+M18+N18+O18+P18 -> -176.92 | R18: =-Q18/$Q$14 -> 0.00015550836 | T18: =SUM(B18:P18) -> -176.92 | V18: =T18-Q18 -> 0
A19: Despesa com Radio e Telefonia Celular | B19: 0 | C19: =0-B19 -> 0 | D19: 0 | E19: 0 | F19: 0 | G19: 0 | H19: 0 | I19: 0 | J19: 0 | K19: 0 | L19: 0 | M19: 0 | N19: 0 | O19: 0 | P19: 0 | Q19: =B19+C19+D19+E19+F19+G19+H19+I19+J19+K19+L19+M19+N19+O19+P19 -> 0 | R19: =-Q19/$Q$14 -> 0 | T19: =SUM(B19:P19) -> 0 | V19: =T19-Q19 -> 0
A20: Equipamento de Segurança - EPIs - 360 | B20: -545.57 | C20: =-3103.7-B20 -> -2558.13 | D20: -725.75 | E20: 0 | F20: 0 | G20: 0 | H20: 0 | I20: 0 | J20: 0 | K20: 0 | L20: 0 | M20: 0 | N20: 0 | O20: 0 | P20: 0 | Q20: =B20+C20+D20+E20+F20+G20+H20+I20+J20+K20+L20+M20+N20+O20+P20 -> -3829.45 | R20: =-Q20/$Q$14 -> 0.003365993 | T20: =SUM(B20:P20) -> -3829.45 | V20: =T20-Q20 -> 0
A21: Ferias - 315 | B21: -6690.01 | C21: =-55840.11-B21 -> -49150.1 | D21: -12532.77 | E21: 0 | F21: 0 | G21: 0 | H21: 0 | I21: 0 | J21: 0 | K21: 0 | L21: 0 | M21: 0 | N21: 0 | O21: 0 | P21: 0 | Q21: =B21+C21+D21+E21+F21+G21+H21+I21+J21+K21+L21+M21+N21+O21+P21 -> -68372.88 | R21: =-Q21/$Q$14 -> 0.060098091 | T21: =SUM(B21:P21) -> -68372.88 | V21: =T21-Q21 -> 0
A22: FGTS - 317 | B22: -3950.11 | C22: =-36146-B22 -> -32195.89 | D22: -8021.56 | E22: 0 | F22: 0 | G22: 0 | H22: 0 | I22: 0 | J22: 0 | K22: 0 | L22: 0 | M22: 0 | N22: 0 | O22: 0 | P22: 0 | Q22: =B22+C22+D22+E22+F22+G22+H22+I22+J22+K22+L22+M22+N22+O22+P22 -> -44167.56 | R22: =-Q22/$Q$14 -> 0.038822206 | T22: =SUM(B22:P22) -> -44167.56 | V22: =T22-Q22 -> 0
A23: Horas Extras - 499 | B23: -2834.22 | C23: =-33881.77-B23 -> -31047.55 | D23: -3895.22 | E23: 0 | F23: 0 | G23: 0 | H23: 0 | I23: 0 | J23: 0 | K23: 0 | L23: 0 | M23: 0 | N23: 0 | O23: 0 | P23: 0 | Q23: =B23+C23+D23+E23+F23+G23+H23+I23+J23+K23+L23+M23+N23+O23+P23 -> -37776.99 | R23: =-Q23/$Q$14 -> 0.033205051 | T23: =SUM(B23:P23) -> -37776.99 | V23: =T23-Q23 -> 0
A24: Indenizações e Aviso Prévio - 318 | B24: 0 | C24: =0-B24 -> 0 | D24: 0 | E24: 0 | F24: 0 | G24: 0 | H24: 0 | I24: 0 | J24: 0 | K24: 0 | L24: 0 | M24: 0 | N24: 0 | O24: 0 | P24: 0 | Q24: =B24+C24+D24+E24+F24+G24+H24+I24+J24+K24+L24+M24+N24+O24+P24 -> 0 | R24: =-Q24/$Q$14 -> 0 | T24: =SUM(B24:P24) -> 0 | V24: =T24-Q24 -> 0
A25: Indenizações Trabalhistas Judiciais - 369 | B25: 0 | C25: =0-B25 -> 0 | D25: 0 | E25: 0 | F25: 0 | G25: 0 | H25: 0 | I25: 0 | J25: 0 | K25: 0 | L25: 0 | M25: 0 | N25: 0 | O25: 0 | P25: 0 | Q25: =B25+C25+D25+E25+F25+G25+H25+I25+J25+K25+L25+M25+N25+O25+P25 -> 0 | R25: =-Q25/$Q$14 -> 0 | T25: =SUM(B25:P25) -> 0 | V25: =T25-Q25 -> 0
A26: INSS - 316 | B26: -4770.4 | C26: =-41125.19-B26 -> -36354.79 | D26: -8823.73 | E26: 0 | F26: 0 | G26: 0 | H26: 0 | I26: 0 | J26: 0 | K26: 0 | L26: 0 | M26: 0 | N26: 0 | O26: 0 | P26: 0 | Q26: =B26+C26+D26+E26+F26+G26+H26+I26+J26+K26+L26+M26+N26+O26+P26 -> -49948.92 | R26: =-Q26/$Q$14 -> 0.04390388 | T26: =SUM(B26:P26) -> -49948.92 | V26: =T26-Q26 -> 0
A27: Locação de Andaimes - 328 | B27: 0 | C27: =0-B27 -> 0 | D27: 0 | E27: 0 | F27: 0 | G27: 0 | H27: 0 | I27: 0 | J27: 0 | K27: 0 | L27: 0 | M27: 0 | N27: 0 | O27: 0 | P27: 0 | Q27: =B27+C27+D27+E27+F27+G27+H27+I27+J27+K27+L27+M27+N27+O27+P27 -> 0 | R27: =-Q27/$Q$14 -> 0 | T27: =SUM(B27:P27) -> 0 | V27: =T27-Q27 -> 0
A28: Locação de Máqs, Ferramentas e Equipamentos - | B28: -11.87 | C28: =-11.87-B28 -> 0 | D28: 0 | E28: 0 | F28: 0 | G28: 0 | H28: 0 | I28: 0 | J28: 0 | K28: 0 | L28: 0 | M28: 0 | N28: 0 | O28: 0 | P28: 0 | Q28: =B28+C28+D28+E28+F28+G28+H28+I28+J28+K28+L28+M28+N28+O28+P28 -> -11.87 | R28: =-Q28/$Q$14 -> 1.043344e-05 | T28: =SUM(B28:P28) -> -11.87 | V28: =T28-Q28 -> 0
A29: Manutenção de Equipamento - 394 | B29: 0 | C29: =0-B29 -> 0 | D29: 0 | E29: 0 | F29: 0 | G29: 0 | H29: 0 | I29: 0 | J29: 0 | K29: 0 | L29: 0 | M29: 0 | N29: 0 | O29: 0 | P29: 0 | Q29: =B29+C29+D29+E29+F29+G29+H29+I29+J29+K29+L29+M29+N29+O29+P29 -> 0 | R29: =-Q29/$Q$14 -> 0 | T29: =SUM(B29:P29) -> 0 | V29: =T29-Q29 -> 0
A30: Manutenção de Veículos - 510 | B30: 0 | C30: =0-B30 -> 0 | D30: 0 | E30: 0 | F30: 0 | G30: 0 | H30: 0 | I30: 0 | J30: 0 | K30: 0 | L30: 0 | M30: 0 | N30: 0 | O30: 0 | P30: 0 | Q30: =B30+C30+D30+E30+F30+G30+H30+I30+J30+K30+L30+M30+N30+O30+P30 -> 0 | R30: =-Q30/$Q$14 -> 0 | T30: =SUM(B30:P30) -> 0 | V30: =T30-Q30 -> 0
A31: Medicina Ocupacional e Assist médica - 3 | B31: -984.52 | C31: =-3598.98-B31 -> -2614.46 | D31: -568 | E31: 0 | F31: 0 | G31: 0 | H31: 0 | I31: 0 | J31: 0 | K31: 0 | L31: 0 | M31: 0 | N31: 0 | O31: 0 | P31: 0 | Q31: =B31+C31+D31+E31+F31+G31+H31+I31+J31+K31+L31+M31+N31+O31+P31 -> -4166.98 | R31: =-Q31/$Q$14 -> 0.0036626736 | T31: =SUM(B31:P31) -> -4166.98 | V31: =T31-Q31 -> 0
A32: Móveis Não Imobilizado - 364 | B32: 0 | C32: =0-B32 -> 0 | D32: 0 | E32: 0 | F32: 0 | G32: 0 | H32: 0 | I32: 0 | J32: 0 | K32: 0 | L32: 0 | M32: 0 | N32: 0 | O32: 0 | P32: 0 | Q32: =B32+C32+D32+E32+F32+G32+H32+I32+J32+K32+L32+M32+N32+O32+P32 -> 0 | R32: =-Q32/$Q$14 -> 0 | T32: =SUM(B32:P32) -> 0 | V32: =T32-Q32 -> 0
A33: Peças, Ferramentas e Acessórios - 361 | B33: -774.52 | C33: =-1417.89-B33 -> -643.37 | D33: -27.9 | E33: 0 | F33: 0 | G33: 0 | H33: 0 | I33: 0 | J33: 0 | K33: 0 | L33: 0 | M33: 0 | N33: 0 | O33: 0 | P33: 0 | Q33: =B33+C33+D33+E33+F33+G33+H33+I33+J33+K33+L33+M33+N33+O33+P33 -> -1445.79 | R33: =-Q33/$Q$14 -> 0.0012708141 | T33: =SUM(B33:P33) -> -1445.79 | V33: =T33-Q33 -> 0
A34: Premios e Gratificacoes - 313 | B34: -29407 | C34: =-255872.91-B34 -> -226465.91 | D34: -40177.24 | E34: 0 | F34: 0 | G34: 0 | H34: 0 | I34: 0 | J34: 0 | K34: 0 | L34: 0 | M34: 0 | N34: 0 | O34: 0 | P34: 0 | Q34: =B34+C34+D34+E34+F34+G34+H34+I34+J34+K34+L34+M34+N34+O34+P34 -> -296050.15 | R34: =-Q34/$Q$14 -> 0.26022085 | T34: =SUM(B34:P34) -> -296050.15 | V34: =T34-Q34 -> 0
A35: Salarios e Ordenados - 311 | B35: -46525.16 | C35: =-399251.49-B35 -> -352726.33 | D35: -87109.87 | E35: 0 | F35: 0 | G35: 0 | H35: 0 | I35: 0 | J35: 0 | K35: 0 | L35: 0 | M35: 0 | N35: 0 | O35: 0 | P35: 0 | Q35: =B35+C35+D35+E35+F35+G35+H35+I35+J35+K35+L35+M35+N35+O35+P35 -> -486361.36 | R35: =-Q35/$Q$14 -> 0.42749975 | T35: =SUM(B35:P35) -> -486361.36 | V35: =T35-Q35 -> 0
A36: Serviços de Terceiros - 324 | B36: 0 | C36: =-72.72-B36 -> -72.72 | D36: 0 | E36: 0 | F36: 0 | G36: 0 | H36: 0 | I36: 0 | J36: 0 | K36: 0 | L36: 0 | M36: 0 | N36: 0 | O36: 0 | P36: 0 | Q36: =B36+C36+D36+E36+F36+G36+H36+I36+J36+K36+L36+M36+N36+O36+P36 -> -72.72 | R36: =-Q36/$Q$14 -> 6.3919103e-05 | T36: =SUM(B36:P36) -> -72.72 | V36: =T36-Q36 -> 0
A37: Seguro Riscos Execução de Serv. Trab. | B37: 0 | C37: =0-B37 -> 0 | D37: 0 | E37: 0 | F37: 0 | G37: 0 | H37: 0 | I37: 0 | J37: 0 | K37: 0 | L37: 0 | M37: 0 | N37: 0 | O37: 0 | P37: 0 | Q37: =B37+C37+D37+E37+F37+G37+H37+I37+J37+K37+L37+M37+N37+O37+P37 -> 0 | R37: =-Q37/$Q$14 -> 0 | T37: =SUM(B37:P37) -> 0 | V37: =T37-Q37 -> 0
A38: Uniformes - 425 | B38: -1829.37 | C38: =-8023.1-B38 -> -6193.73 | D38: -811.24 | E38: 0 | F38: 0 | G38: 0 | H38: 0 | I38: 0 | J38: 0 | K38: 0 | L38: 0 | M38: 0 | N38: 0 | O38: 0 | P38: 0 | Q38: =B38+C38+D38+E38+F38+G38+H38+I38+J38+K38+L38+M38+N38+O38+P38 -> -8834.34 | R38: =-Q38/$Q$14 -> 0.007765169 | T38: =SUM(B38:P38) -> -8834.34 | V38: =T38-Q38 -> 0
A39: Vale Transporte e Condução - 321 | B39: -4349.64 | C39: =-38410.3-B39 -> -34060.66 | D39: -9534.45 | E39: 0 | F39: 0 | G39: 0 | H39: 0 | I39: 0 | J39: 0 | K39: 0 | L39: 0 | M39: 0 | N39: 0 | O39: 0 | P39: 0 | Q39: =B39+C39+D39+E39+F39+G39+H39+I39+J39+K39+L39+M39+N39+O39+P39 -> -47944.75 | R39: =-Q39/$Q$14 -> 0.042142263 | T39: =SUM(B39:P39) -> -47944.75 | V39: =T39-Q39 -> 0
A40: 13º Salario - 314 | B40: -3124.79 | C40: =-40352.95-B40 -> -37228.16 | D40: -9800.8 | E40: 0 | F40: 0 | G40: 0 | H40: 0 | I40: 0 | J40: 0 | K40: 0 | L40: 0 | M40: 0 | N40: 0 | O40: 0 | P40: 0 | Q40: =B40+C40+D40+E40+F40+G40+H40+I40+J40+K40+L40+M40+N40+O40+P40 -> -50153.75 | R40: =-Q40/$Q$14 -> 0.044083921 | T40: =SUM(B40:P40) -> -50153.75 | V40: =T40-Q40 -> 0
A41: Cursos e treinamentos | B41: 0 | C41: =0-B41 -> 0 | D41: 0 | E41: 0 | F41: 0 | G41: 0 | H41: 0 | I41: 0 | J41: 0 | K41: 0 | L41: 0 | M41: 0 | N41: 0 | O41: 0 | P41: 0 | Q41: =B41+C41+D41+E41+F41+G41+H41+I41+J41+K41+L41+M41+N41+O41+P41 -> 0 | R41: =-Q41/$Q$14 -> 0 | T41: =SUM(B41:P41) -> 0 | V41: =T41-Q41 -> 0
A42: Confraternização de Funcionários | B42: 0 | C42: 0 | D42: =SUM(E42:P42) -> 0 | E42: 0 | F42: 0 | G42: 0 | H42: 0 | I42: 0 | J42: 0 | K42: 0 | L42: 0 | M42: 0 | N42: 0 | O42: 0 | P42: 0 | Q42: =B42+C42+D42+E42+F42+G42+H42+I42+J42+K42+L42+M42+N42+O42+P42 -> 0 | R42: =-Q42/$Q$14 -> 0 | T42: =SUM(B42:P42) -> 0 | V42: =T42-Q42 -> 0
A43: Custos Total... | B43: =SUM(B17:B42) -> -112843.57 | C43: =SUM(C17:C42) -> -883730.46 | D43: =SUM(D17:D42) -> -206344.11 | E43: =SUM(E17:E42) -> 0 | F43: =SUM(F17:F42) -> 0 | G43: =SUM(G17:G42) -> 0 | H43: =SUM(H17:H42) -> 0 | I43: =SUM(I17:I42) -> 0 | ... Q43: =SUM(Q17:Q42) -> -1202918.1 | R43: =-Q43/$Q$14 -> 1.0573356 | T43: =SUM(B43:P43) -> -1202918.1 | V43: =T43-Q43 -> 0
T44: =SUM(B44:P44) -> 0 | V44: =T44-Q44 -> 0
A45: = Lucro/Prejuízo Bruto | B45: =B14+B43 -> -112843.57 | C45: =C14+C43 -> 149239.02 | D45: =D14+D43 -> -101625.53 | E45: =E14+E43 -> 0 | F45: =F14+F43 -> 0 | G45: =G14+G43 -> 0 | H45: =H14+H43 -> 0 | I45: =I14+I43 -> 0 | ... P45: =P14+P43 -> 0 | Q45: =B45+C45+D45+E45+F45+G45+H45+I45+J45+K45+L45+M45+N45+O45+P45 -> -65230.08 | R45: =-Q45/$Q$14 -> 0.057335646 | T45: =SUM(B45:P45) -> -65230.08 | V45: =T45-Q45 -> 0
...

Sheet OBRA 268
A1: BELA NOVA CONSTRUTORA EIRELI
A3: DEMONSTRAÇÃO DO RESULTADO APURADO
A5: OBRA 268 - EREDITA - EZTEC
A7: OBRA ENCERRADA
B9: Out a Dez/2022 | C9: Jan a Dez/23 | D9: Janeiro/2024 | E9: Fevereiro/2024 | F9: Março/2024 | G9: Abril/2024 | H9: Maio/2024 | I9: Junho/2024 | J9: Julho/2024 | K9: Agosto/2024 | L9: Setembro/2024 | M9: Outubro/2024 | N9: Novembro/2024 | O9: Dezembro/2024 | P9: Acumulado | Q9: % S/FAT
A10: Receitas Brutas
A11: Servicos prestados | B11: 233796.98 | C11: =687246.83-B11 -> 453449.85 | D11: 0 | E11: 0 | F11: 0 | G11: 0 | H11: 0 | I11: 0 | J11: 0 | K11: 0 | L11: 0 | M11: 0 | N11: 0 | O11: 0 | P11: =B11+C11+D11+E11+F11+G11+H11+I11+J11+K11+L11+M11+N11+O11 -> 687246.83 | Q11: 1 | S11: =SUM(B11:H11) -> 687246.83 | U11: =S11-P11 -> 0
A12: Locação de Equipamentos - 450 | B12: 0 | C12: 0 | D12: 0 | E12: 0 | F12: 0 | G12: 0 | H12: 0 | I12: 0 | J12: 0 | K12: 0 | L12: 0 | M12: 0 | N12: 0 | O12: 0 | P12: =B12+C12+D12+E12+F12+G12+H12+I12+J12+K12+L12+M12+N12+O12 -> 0 | S12: =SUM(B12:H12) -> 0 | U12: =S12-P12 -> 0
A13: Receitas Brutas Total... | B13: =B11+B12 -> 233796.98 | C13: =SUM(C11:C12) -> 453449.85 | D13: =D11+D12 -> 0 | E13: =E11+E12 -> 0 | F13: =F11 -> 0 | G13: =G11 -> 0 | H13: =H11 -> 0 | I13: =I11 -> 0 | J13: =J11 -> 0 | K13: =K11 -> 0 | L13: =L11 -> 0 | M13: =M11 -> 0 | ... O13: =O11 -> 0 | P13: =SUM(P11:P12) -> 687246.83 | Q13: 1 | S13: =SUM(B13:H13) -> 687246.83 | U13: =S13-P13 -> 0
S14: =SUM(B14:H14) -> 0 | U14: =S14-P14 -> 0
A15: Custos | S15: =SUM(B15:H15) -> 0 | U15: =S15-P15 -> 0
A16: Alimentação - 320 | B16: -3481.54 | C16: =-35095.93-B16 -> -31614.39 | D16: 0 | E16: 0 | F16: 0 | G16: 0 | H16: 0 | I16: 0 | J16: 0 | K16: 0 | L16: 0 | M16: 0 | N16: 0 | O16: 0 | P16: =B16+C16+D16+E16+F16+G16+H16+I16+J16+K16+L16+M16+N16+O16 -> -35095.93 | Q16: =-P16/$P$11 -> 0.051067431 | S16: =SUM(B16:H16) -> -35095.93 | U16: =S16-P16 -> 0
A17: Combustíveis - 322 | B17: -176.92 | C17: =-176.92-B17 -> 0 | D17: 0 | E17: 0 | F17: 0 | G17: 0 | H17: 0 | I17: 0 | J17: 0 | K17: 0 | L17: 0 | M17: 0 | N17: 0 | O17: 0 | P17: =B17+C17+D17+E17+F17+G17+H17+I17+J17+K17+L17+M17+N17+O17 -> -176.92 | Q17: =-P17/$P$11 -> 0.00025743298 | S17: =SUM(B17:H17) -> -176.92 | U17: =S17-P17 -> 0
A18: Despesa com Radio e Telefonia Celular | B18: 0 | C18: =0-B18 -> 0 | D18: 0 | E18: 0 | F18: 0 | G18: 0 | H18: 0 | I18: 0 | J18: 0 | K18: 0 | L18: 0 | M18: 0 | N18: 0 | O18: 0 | P18: =B18+C18+D18+E18+F18+G18+H18+I18+J18+K18+L18+M18+N18+O18 -> 0 | Q18: =-P18/$P$11 -> 0 | S18: =SUM(B18:H18) -> 0 | U18: =S18-P18 -> 0
A19: Equipamento de Segurança - EPIs - 360 | B19: -319.3 | C19: =-340.27-B19 -> -20.97 | D19: 0 | E19: 0 | F19: 0 | G19: 0 | H19: 0 | I19: 0 | J19: 0 | K19: 0 | L19: 0 | M19: 0 | N19: 0 | O19: 0 | P19: =B19+C19+D19+E19+F19+G19+H19+I19+J19+K19+L19+M19+N19+O19 -> -340.27 | Q19: =-P19/$P$11 -> 0.00049512051 | S19: =SUM(B19:H19) -> -340.27 | U19: =S19-P19 -> 0
A20: Ferias - 315 | B20: -3345 | C20: =-27438.66-B20 -> -24093.66 | D20: -312.12 | E20: -312.12 | F20: -312.12 | G20: -312.12 | H20: -326.25 | I20: 0 | J20: 0 | K20: 0 | L20: 0 | M20: 0 | N20: 0 | O20: 0 | P20: =B20+C20+D20+E20+F20+G20+H20+I20+J20+K20+L20+M20+N20+O20 -> -29013.39 | Q20: =-P20/$P$11 -> 0.042216841 | S20: =SUM(B20:H20) -> -29013.39 | U20: =S20-P20 -> 0
A21: FGTS - 317 | B21: -1662.39 | C21: =-16909.44-B21 -> -15247.05 | D21: -192.4 | E21: -192.4 | F21: -192.4 | G21: -192.4 | H21: -201.11 | I21: 0 | J21: 0 | K21: 0 | L21: 0 | M21: 0 | N21: 0 | O21: 0 | P21: =B21+C21+D21+E21+F21+G21+H21+I21+J21+K21+L21+M21+N21+O21 -> -17880.15 | Q21: =-P21/$P$11 -> 0.026017072 | S21: =SUM(B21:H21) -> -17880.15 | U21: =S21-P21 -> 0
A22: Horas Extras - 499 | B22: -850.72 | C22: =-7772.22-B22 -> -6921.5 | D22: 0 | E22: 0 | F22: 0 | G22: 0 | H22: 0 | I22: 0 | J22: 0 | K22: 0 | L22: 0 | M22: 0 | N22: 0 | O22: 0 | P22: =B22+C22+D22+E22+F22+G22+H22+I22+J22+K22+L22+M22+N22+O22 -> -7772.22 | Q22: =-P22/$P$11 -> 0.011309212 | S22: =SUM(B22:H22) -> -7772.22 | U22: =S22-P22 -> 0
A23: Indenizações e Aviso Prévio - 318 | B23: 0 | C23: =5252.36-B23 -> 5252.36 | D23: 0 | E23: 0 | F23: 0 | G23: 0 | H23: 0 | I23: 0 | J23: 0 | K23: 0 | L23: 0 | M23: 0 | N23: 0 | O23: 0 | P23: =B23+C23+D23+E23+F23+G23+H23+I23+J23+K23+L23+M23+N23+O23 -> 5252.36 | Q23: =P23/$P$11 -> 0.0076426107 | S23: =SUM(B23:H23) -> 5252.36 | U23: =S23-P23 -> 0
A24: Indenizações Trabalhistas Judiciais - 369 | B24: 1313.9 | C24: =1313.9-B24 -> 0 | D24: 0 | E24: 0 | F24: 0 | G24: 0 | H24: 0 | I24: 0 | J24: 0 | K24: 0 | L24: 0 | M24: 0 | N24: 0 | O24: 0 | P24: =B24+C24+D24+E24+F24+G24+H24+I24+J24+K24+L24+M24+N24+O24 -> 1313.9 | Q24: =P24/$P$11 -> 0.0019118313 | S24: =SUM(B24:H24) -> 1313.9 | U24: =S24-P24 -> 0
A25: INSS - 316 | B25: -2008.73 | C25: =-17755.96-B25 -> -15747.23 | D25: 0 | E25: 0 | F25: 0 | G25: 0 | H25: 0 | I25: 0 | J25: 0 | K25: 0 | L25: 0 | M25: 0 | N25: 0 | O25: 0 | P25: =B25+C25+D25+E25+F25+G25+H25+I25+J25+K25+L25+M25+N25+O25 -> -17755.96 | Q25: =-P25/$P$11 -> 0.025836365 | S25: =SUM(B25:H25) -> -17755.96 | U25: =S25-P25 -> 0
A26: Locação de Andaimes - 328 | B26: 0 | C26: =0-B26 -> 0 | D26: 0 | E26: 0 | F26: 0 | G26: 0 | H26: 0 | I26: 0 | J26: 0 | K26: 0 | L26: 0 | M26: 0 | N26: 0 | O26: 0 | P26: =B26+C26+D26+E26+F26+G26+H26+I26+J26+K26+L26+M26+N26+O26 -> 0 | Q26: =-P26/$P$11 -> 0 | S26: =SUM(B26:H26) -> 0 | U26: =S26-P26 -> 0
A27: Locação de Máqs, Ferramentas e Equipamentos - | B27: -11.87 | C27: =-11.87-B27 -> 0 | D27: 0 | E27: 0 | F27: 0 | G27: 0 | H27: 0 | I27: 0 | J27: 0 | K27: 0 | L27: 0 | M27: 0 | N27: 0 | O27: 0 | P27: =B27+C27+D27+E27+F27+G27+H27+I27+J27+K27+L27+M27+N27+O27 -> -11.87 | Q27: =-P27/$P$11 -> 1.7271815e-05 | S27: =SUM(B27:H27) -> -11.87 | U27: =S27-P27 -> 0
A28: Manutenção de Equipamento - 394 | B28: 0 | C28: =0-B28 -> 0 | D28: 0 | E28: 0 | F28: 0 | G28: 0 | H28: 0 | I28: 0 | J28: 0 | K28: 0 | L28: 0 | M28: 0 | N28: 0 | O28: 0 | P28: =B28+C28+D28+E28+F28+G28+H28+I28+J28+K28+L28+M28+N28+O28 -> 0 | Q28: =-P28/$P$11 -> 0 | S28: =SUM(B28:H28) -> 0 | U28: =S28-P28 -> 0
A29: Manutenção de Veículos - 510 | B29: 0 | C29: =0-B29 -> 0 | D29: 0 | E29: 0 | F29: 0 | G29: 0 | H29: 0 | I29: 0 | J29: 0 | K29: 0 | L29: 0 | M29: 0 | N29: 0 | O29: 0 | P29: =B29+C29+D29+E29+F29+G29+H29+I29+J29+K29+L29+M29+N29+O29 -> 0 | Q29: =-P29/$P$11 -> 0 | S29: =SUM(B29:H29) -> 0 | U29: =S29-P29 -> 0
A30: Medicina Ocupacional e Assist médica - 3 | B30: -547.35 | C30: =-2067.01-B30 -> -1519.66 | D30: 0 | E30: 0 | F30: 0 | G30: 0 | H30: 0 | I30: 0 | J30: 0 | K30: 0 | L30: 0 | M30: 0 | N30: 0 | O30: 0 | P30: =B30+C30+D30+E30+F30+G30+H30+I30+J30+K30+L30+M30+N30+O30 -> -2067.01 | Q30: =-P30/$P$11 -> 0.0030076676 | S30: =SUM(B30:H30) -> -2067.01 | U30: =S30-P30 -> 0
A31: Móveis Não Imobilizado - 364 | B31: 0 | C31: =0-B31 -> 0 | D31: 0 | E31: 0 | F31: 0 | G31: 0 | H31: 0 | I31: 0 | J31: 0 | K31: 0 | L31: 0 | M31: 0 | N31: 0 | O31: 0 | P31: =B31+C31+D31+E31+F31+G31+H31+I31+J31+K31+L31+M31+N31+O31 -> 0 | Q31: =-P31/$P$11 -> 0 | S31: =SUM(B31:H31) -> 0 | U31: =S31-P31 -> 0
A32: Peças, Ferramentas e Acessórios - 361 | B32: 0 | C32: =-172.08-B32 -> -172.08 | D32: 0 | E32: 0 | F32: 0 | G32: 0 | H32: 0 | I32: 0 | J32: 0 | K32: 0 | L32: 0 | M32: 0 | N32: 0 | O32: 0 | P32: =B32+C32+D32+E32+F32+G32+H32+I32+J32+K32+L32+M32+N32+O32 -> -172.08 | Q32: =-P32/$P$11 -> 0.00025039039 | S32: =SUM(B32:H32) -> -172.08 | U32: =S32-P32 -> 0
A33: Premios e Gratificacoes - 313 | B33: -9281 | C33: =-89210-B33 -> -79929 | D33: 0 | E33: 0 | F33: 0 | G33: 0 | H33: 0 | I33: 0 | J33: 0 | K33: 0 | L33: 0 | M33: 0 | N33: 0 | O33: 0 | P33: =B33+C33+D33+E33+F33+G33+H33+I33+J33+K33+L33+M33+N33+O33 -> -89210 | Q33: =-P33/$P$11 -> 0.1298078 | S33: =SUM(B33:H33) -> -89210 | U33: =S33-P33 -> 0
A34: Salarios e Ordenados - 311 | B34: -19744.89 | C34: =-180672-B34 -> -160927.11 | D34: 0 | E34: 0 | F34: 0 | G34: 0 | H34: 0 | I34: 0 | J34: 0 | K34: 0 | L34: 0 | M34: 0 | N34: 0 | O34: 0 | P34: =B34+C34+D34+E34+F34+G34+H34+I34+J34+K34+L34+M34+N34+O34 -> -180672 | Q34: =-P34/$P$11 -> 0.26289245 | S34: =SUM(B34:H34) -> -180672 | U34: =S34-P34 -> 0
A35: Serviços de Terceiros - 324 | B35: 0 | C35: =-72.72-B35 -> -72.72 | D35: 0 | E35: 0 | F35: 0 | G35: 0 | H35: 0 | I35: 0 | J35: 0 | K35: 0 | L35: 0 | M35: 0 | N35: 0 | O35: 0 | P35: =B35+C35+D35+E35+F35+G35+H35+I35+J35+K35+L35+M35+N35+O35 -> -72.72 | Q35: =-P35/$P$11 -> 0.00010581351 | S35: =SUM(B35:H35) -> -72.72 | U35: =S35-P35 -> 0
A36: Seguro Riscos Execução de Serv. Trab. | B36: 0 | C36: =0-B36 -> 0 | D36: 0 | E36: 0 | F36: 0 | G36: 0 | H36: 0 | I36: 0 | J36: 0 | K36: 0 | L36: 0 | M36: 0 | N36: 0 | O36: 0 | P36: =B36+C36+D36+E36+F36+G36+H36+I36+J36+K36+L36+M36+N36+O36 -> 0 | Q36: =-P36/$P$11 -> 0 | S36: =SUM(B36:H36) -> 0 | U36: =S36-P36 -> 0
A37: Uniformes - 425 | B37: -728.46 | C37: =-3306-B37 -> -2577.54 | D37: 0 | E37: 0 | F37: 0 | G37: 0 | H37: 0 | I37: 0 | J37: 0 | K37: 0 | L37: 0 | M37: 0 | N37: 0 | O37: 0 | P37: =B37+C37+D37+E37+F37+G37+H37+I37+J37+K37+L37+M37+N37+O37 -> -3306 | Q37: =-P37/$P$11 -> 0.0048104987 | S37: =SUM(B37:H37) -> -3306 | U37: =S37-P37 -> 0
A38: Vale Transporte e Condução - 321 | B38: -1345.92 | C38: =-16865.8-B38 -> -15519.88 | D38: 0 | E38: 0 | F38: 0 | G38: 0 | H38: 0 | I38: 0 | J38: 0 | K38: 0 | L38: 0 | M38: 0 | N38: 0 | O38: 0 | P38: =B38+C38+D38+E38+F38+G38+H38+I38+J38+K38+L38+M38+N38+O38 -> -16865.8 | Q38: =-P38/$P$11 -> 0.02454111 | S38: =SUM(B38:H38) -> -16865.8 | U38: =S38-P38 -> 0
A39: 13º Salario - 314 | B39: -2450.27 | C39: =-20573.66-B39 -> -18123.39 | D39: 0 | E39: 0 | F39: 0 | G39: 0 | H39: 0 | I39: 0 | J39: 0 | K39: 0 | L39: 0 | M39: 0 | N39: 0 | O39: 0 | P39: =B39+C39+D39+E39+F39+G39+H39+I39+J39+K39+L39+M39+N39+O39 -> -20573.66 | Q39: =-P39/$P$11 -> 0.029936348 | S39: =SUM(B39:H39) -> -20573.66 | U39: =S39-P39 -> 0
A40: Cursos e treinamentos | B40: 0 | C40: =0-B40 -> 0 | D40: 0 | E40: 0 | F40: 0 | G40: 0 | H40: 0 | I40: 0 | J40: 0 | K40: 0 | L40: 0 | M40: 0 | N40: 0 | O40: 0 | P40: =B40+C40+D40+E40+F40+G40+H40+I40+J40+K40+L40+M40+N40+O40 -> 0 | Q40: =-P40/$P$11 -> 0 | S40: =SUM(B40:H40) -> 0 | U40: =S40-P40 -> 0
A41: Confraternização de Funcionários | B41: 0 | C41: 0 | D41: 0 | E41: 0 | F41: 0 | G41: 0 | H41: 0 | I41: 0 | J41: 0 | K41: 0 | L41: 0 | M41: 0 | N41: 0 | O41: 0 | P41: =B41+C41+D41+E41+F41+G41+H41+I41+J41+K41+L41+M41+N41+O41 -> 0 | Q41: =-P41/$P$11 -> 0 | S41: =SUM(B41:H41) -> 0 | U41: =S41-P41 -> 0
A42: Custos Total... | B42: =SUM(B16:B41) -> -44640.46 | C42: =SUM(C16:C41) -> -367233.82 | D42: =SUM(D16:D41) -> -504.52 | E42: =SUM(E16:E41) -> -504.52 | F42: =SUM(F16:F41) -> -504.52 | G42: =SUM(G16:G41) -> -504.52 | H42: =SUM(H16:H41) -> -527.36 | I42: =SUM(I16:I41) -> 0 | ... P42: =SUM(P16:P41) -> -414419.72 | Q42: =-P42/$P$11 -> 0.60301438 | S42: =SUM(B42:H42) -> -414419.72 | U42: =S42-P42 -> 0
I43: =SUM(I16:I41) -> 0 | J43: =SUM(J16:J41) -> 0 | K43: =SUM(K16:K41) -> 0 | L43: =SUM(L16:L41) -> 0 | M43: =SUM(M16:M41) -> 0 | N43: =SUM(N16:N41) -> 0 | O43: =SUM(O16:O41) -> 0 | S43: =SUM(B43:H43) -> 0 | U43: =S43-P43 -> 0
A44: = Lucro/Prejuízo Bruto | B44: =B13+B42 -> 189156.52 | C44: =C13+C42 -> 86216.03 | D44: =D13+D42 -> -504.52 | E44: =E13+E42 -> -504.52 | F44: =F13+F42 -> -504.52 | G44: =G13+G42 -> -504.52 | H44: =H13+H42 -> -527.36 | I44: =I13+I42 -> 0 | ... O44: =O13+O42 -> 0 | P44: =B44+C44+D44+E44+F44+G44+H44+I44+J44+K44+L44+M44+N44+O44 -> 272827.11 | Q44: =P44/$P$11 -> 0.39698562 | S44: =SUM(B44:H44) -> 272827.11 | U44: =S44-P44 -> 0
...

Sheet OBRA 269
A1: DEMONSTRAÇÃO DO RESULTADO APURADO
A3: OBRA 269 - V.B FARIA LIMA - BUENO NETO
A5: OBRA ENCERRADA
B7: Ago a Dez/2023 | C7: Janeiro/2024 | D7: Fevereiro/2024 | E7: Março/2024 | F7: Abril/2024 | G7: Maio/2024 | H7: Junho/2024 | I7: Julho/2024 | J7: Agosto/2024 | K7: Setembro/2024 | L7: Outubro/2024 | M7: Novembro/2024 | N7: Dezembro/2024 | O7: Acumulado | P7: % S/FAT
A8: Receitas Brutas
A9: Servicos prestados | B9: 0 | C9: 0 | D9: 0 | E9: 0 | F9: 0 | G9: 0 | H9: 0 | I9: 0 | J9: 0 | K9: 0 | L9: 0 | M9: 0 | N9: 0 | O9: =B9+C9+D9+E9+F9+G9+H9+I9+J9+K9+L9+M9+N9 -> 0 | P9: 1 | R9: =SUM(B9:E9) -> 0 | S9: =R9-O9 -> 0
A10: Locação de Equipamentos - 450 | B10: 0 | C10: 0 | D10: 0 | E10: 0 | F10: 0 | G10: 0 | H10: 0 | I10: 0 | J10: 0 | K10: 0 | L10: 0 | M10: 0 | N10: 0 | O10: =B10+C10+D10+E10+F10+G10+H10+I10+J10+K10+L10+M10+N10 -> 0 | R10: =SUM(B10:E10) -> 0 | S10: =R10-O10 -> 0
A11: Receitas Brutas Total... | B11: =SUM(B9:B10) -> 0 | C11: =SUM(C9:C10) -> 0 | D11: =SUM(D9:D10) -> 0 | E11: =SUM(E9:E10) -> 0 | F11: =SUM(F9:F10) -> 0 | G11: =SUM(G9:G10) -> 0 | H11: =SUM(H9:H10) -> 0 | I11: =SUM(I9:I10) -> 0 | ... O11: =SUM(O9:O10) -> 0 | P11: 1 | R11: =SUM(B11:E11) -> 0 | S11: =R11-O11 -> 0
R12: =SUM(B12:E12) -> 0 | S12: =R12-O12 -> 0
A13: Custos | R13: =SUM(B13:E13) -> 0 | S13: =R13-O13 -> 0
